Workbook

Sheet PLANILLA GENERAL ABRIL 2026
A1: Índice | B1: RUT (sin puntos y con guion) | C1: ID (rut sin puntos, sin guión ni digito vertificador) | D1: APELLIDO PATERNO | E1: APELLIDO MATERNO | F1: NOMBRES | G1: CARGO | H1: INICIO DE CONTRATO | I1: D/I | J1: GENERO M/F | K1: TURNO (5x2-4x3-14x14 -art22) | L1: CC | M1: 1 | N1: 2 | O1: 3 | P1: 4 | Q1: 5 | R1: 6 | S1: 7 | T1: 8 | U1: 9 | V1: 10 | W1: 11 | X1: 12 | Y1: 13 | Z1: 14 | AA1: 15 | AB1: 16 | AC1: 17 | AD1: 18 | AE1: 19 | AF1: 20 | AG1: 21 | AH1: 22 | AI1: 23 | AJ1: 24 | AK1: 25 | AL1: 26 | AM1: 27 | AN1: 28 | AO1: 29 | AP1: 30 | AQ1: 31 | AR1: (1) | AS1: (2) | AT1: (3) | AU1: (4) | AV1: (5) | AW1: (6) | AX1: (7) | AY1: (8) | AZ1: (9) | BA1: T.D.T. | BB1: 1033-Bono Gestión Variable | BC1: 1029-Bono Compensatorio descanso | BD1: Justificación Bono 10-29 (Compensatorio descanso) | BE1: 1034-Bono Incentivo variable | BF1: Justificación Bono 1034 (Incentivo variable) | BG1: 1140-Bono Responsabilidad 2 | BH1: Justificación 1140 (Bono Responsabilidad) | BI1: 1041-Bono Terreno (Exclusivo proyecto Techint-CMDIC) | BJ1: 1031-Bono Escolaridad I/T (Uso exclusivo Area de Compensaciones) | BK1: 1092-Diferencia de haber | BL1: Justificación Bono 1092 (Diferencia de Haber) | BM1: Cantidad de feriados del mes | BN1: 1082-Bono Compens. Feriado | BO1: 1020-Aguinaldo I/T | BP1: 1140-Bono de Permanencia (Plan de Beneficios) | BQ1: Bono Seguridad BESALCO-MEL | BR1: Bono Q1 (Exclusivo Collahuasi) | BS1: Bono Q2 (Exclusivo Collahuasi) | BT1: Bono Q3 (Exclusivo Collahuasi) | BU1: Bono Q4 (Exclusivo Collahuasi) | BV1: Bono RSA (Exclusivo Collahuasi) | BW1: 1044-Asignación Colación | BX1: Justificación Asignacion Colacion | BY1: 1165-Asignación Movilización 2 | BZ1: Justificación Asignación Movilización 2 | CA1: 1172-Viatico 2 | CB1: Justificación Viatico | CC1: SALA CUNA | CD1: Justificaciión de Asignación (Detalle del beneficio) | CE1: 1032-Bono Escolaridad N/I | CF1: 1124-Asignación familiar Retroactiva | CG1: Descuento por aporte voluntario | CH1: Observaciones generales | CI1: ACUERDO MARCO ACCIONA-CODELCO | CJ1: GRATIFICACION ACUERD MARCO ACCIONA-CODELCO2 | CK1: DIAS ADICIONALES CHIQUICAMATA | CL1: BONO PARTICIPACION CHIQUI | CM1: RETENCION JUDICIAL | CN1: PRESTAMO EMPRESA | CO1: LOS HEROES | CP1: LA ARAUCANA | CQ1: SEGURO | CR1: FALP
A2: 1 | B2: 7365743-1 | C2: 7365743 | D2: BONE | E2: SANTIS | F2: CARLOS ALBERTO | G2: GERENTE GENERAL | I2: I | J2: M | K2: 5X2 | L2: 1710000001 | M2: 1 | N2: 1 | O2: 3 | P2: 3 | Q2: 3 | R2: 1 | S2: 1 | T2: 1 | U2: 1 | V2: 1 | W2: 3 | X2: 3 | Y2: 1 | Z2: 1 | AA2: 1 | AB2: 1 | AC2: 1 | AD2: 3 | AE2: 3 | AF2: 1 | AG2: 1 | AH2: 1 | AI2: 1 | AJ2: 1 | AK2: 3 | AL2: 3 | AM2: 1 | AN2: 1 | AO2: 1 | AP2: 1 | AR2: 21 | AS2: 0 | AT2: 9 | AU2: 0 | AV2: 0 | AW2: 0 | AX2: 0 | AY2: 0 | AZ2: 0 | BA2: 30 | CN2: 601803 | CO2: =VLOOKUP(C2,'LOS HEROES'!$A$2:$D$30,4,0) -> 552163 | CP2: 0 | CQ2: =VLOOKUP(C2,SEGURO!$A$2:$C$28,3,0) -> 46667 | CR2: 0
A3: 2 | B3: 9187205-6 | C3: 9187205 | D3: HERRERA | E3: VERA | F3: OSCAR CRISTIAN | G3: GERENTE DE PROYECTOS | H3: 45676 | I3: I | J3: M | K3: 4X3 | L3: 1790000088 | M3: 1 | N3: 1 | O3: 3 | P3: 3 | Q3: 3 | R3: 1 | S3: 1 | T3: 1 | U3: 1 | V3: 3 | W3: 3 | X3: 3 | Y3: 1 | Z3: 1 | AA3: 1 | AB3: 1 | AC3: 3 | AD3: 3 | AE3: 3 | AF3: 1 | AG3: 1 | AH3: 1 | AI3: 1 | AJ3: 3 | AK3: 3 | AL3: 3 | AM3: 1 | AN3: 1 | AO3: 1 | AP3: 1 | AR3: 18 | AS3: 0 | AT3: 12 | AU3: 0 | AV3: 0 | AW3: 0 | AX3: 0 | AY3: 0 | AZ3: 0 | BA3: 30 | BE3: 328000 | BF3: Bono para llegar a sueldo pactado | BM3: 0 | CP3: 0 | CQ3: 0 | CR3: 0
A4: 3 | B4: 9205219-2 | C4: 9205219 | D4: JOGLAR | E4: ZAMBRANA | F4: ADOLFO | G4: GERENTE GESTION PERSONAS | I4: I | J4: M | K4: 5X2 | L4: 1720000001 | M4: 1 | N4: 1 | O4: 3 | P4: 3 | Q4: 3 | R4: 1 | S4: 1 | T4: 1 | U4: 1 | V4: 3 | W4: 3 | X4: 3 | Y4: 1 | Z4: 1 | AA4: 1 | AB4: 1 | AC4: 3 | AD4: 3 | AE4: 3 | AF4: 1 | AG4: 1 | AH4: 1 | AI4: 1 | AJ4: 3 | AK4: 3 | AL4: 3 | AM4: 1 | AN4: 1 | AO4: 1 | AP4: 1 | AR4: 18 | AS4: 0 | AT4: 12 | AU4: 0 | AV4: 0 | AW4: 0 | AX4: 0 | AY4: 0 | AZ4: 0 | BA4: 30 | CP4: 0 | CQ4: =VLOOKUP(C4,SEGURO!$A$2:$C$28,3,0) -> 46667 | CR4: 0
A5: 4 | B5: 9430404-0 | C5: 9430404 | D5: BARRIA | E5: BARRIENTOS | F5: HARRY ISMAEL | G5: ENCARGADO TALLER MANTENCION | I5: I | J5: M | K5: 5X2 | L5: 1740000002 | M5: 1 | N5: 1 | O5: 3 | P5: 3 | Q5: 3 | R5: 9 | S5: 9 | T5: 9 | U5: 9 | V5: 9 | W5: 9 | X5: 9 | Y5: 9 | Z5: 9 | AA5: 9 | AB5: 9 | AC5: 9 | AD5: 9 | AE5: 9 | AF5: 1 | AG5: 1 | AH5: 1 | AI5: 1 | AJ5: 1 | AK5: 3 | AL5: 3 | AM5: 1 | AN5: 1 | AO5: 1 | AP5: 1 | AR5: 11 | AS5: 0 | AT5: 5 | AU5: 0 | AV5: 0 | AW5: 0 | AX5: 0 | AY5: 0 | AZ5: 14 | BA5: 30 | BY5: 40000 | CA5: 30000 | CB5: Viatico para traslado terminal buses oficina (4 am) | CO5: =VLOOKUP(C5,'LOS HEROES'!$A$2:$D$30,4,0) -> 64673 | CP5: 0 | CQ5: =VLOOKUP(C5,SEGURO!$A$2:$C$28,3,0) -> 18779 | CR5: 0
A6: 5 | B6: 9460969-0 | C6: 9460969 | D6: ARANDA | E6: CAQUEO | F6: LUIS ALFONSO | G6: EXPEDITOR | H6: 45712 | I6: I | J6: M | K6: A | L6: 1790000088 | M6: 1 | N6: 3 | O6: 3 | P6: 3 | AR6: 1 | AS6: 0 | AT6: 3 | AU6: 0 | AV6: 0 | AW6: 0 | AX6: 0 | AY6: 0 | AZ6: 0 | BA6: 4 | BC6: 193599 | BD6: Corresponde a dia pend. Cambio jornada 4x3 transición. | BE6: 33333.333 | BF6: para ajustar sueldo pactado a 1.700.000.- | BM6: 0 | BP6: 75000 | CP6: 0 | CQ6: 0 | CR6: 0
A7: 6 | B7: 9717041-K | C7: 9717041 | D7: OLIVARES | E7: DIAZ | F7: GONZALO LUIS | G7: ENCARGADO DE COMPRAS Y ABASTECIMIENTO | I7: I | J7: M | K7: 5X2 | L7: 1790000088 | M7: 1 | N7: 1 | O7: 3 | P7: 3 | Q7: 3 | R7: 1 | S7: 1 | T7: 1 | U7: 1 | V7: 1 | W7: 3 | X7: 3 | Y7: 1 | Z7: 1 | AA7: 1 | AB7: 1 | AC7: 1 | AD7: 3 | AE7: 3 | AF7: 1 | AG7: 1 | AH7: 1 | AI7: 1 | AJ7: 1 | AK7: 3 | AL7: 3 | AM7: 1 | AN7: 1 | AO7: 1 | AP7: 1 | AR7: 21 | AS7: 0 | AT7: 9 | AU7: 0 | AV7: 0 | AW7: 0 | AX7: 0 | AY7: 0 | AZ7: 0 | BA7: 30 | BW7: 110000 | CO7: =VLOOKUP(C7,'LOS HEROES'!$A$2:$D$30,4,0) -> 100429 | CP7: 0 | CQ7: 0 | CR7: 0
A8: 7 | B8: 9809267-6 | C8: 9809267 | D8: ANGEL | E8: GOMEZ | F8: SERGIO ERNESTO | G8: AYUDANTE GEOSINTETICOS | H8: 46096 | I8: D | J8: M | K8: 7X7 | L8: 1790000091 | M8: 3 | N8: 3 | O8: 3 | P8: 3 | Q8: 3 | R8: 3 | S8: 3 | T8: 2 | U8: 2 | V8: 2 | W8: 2 | X8: 2 | Y8: 2 | Z8: 2 | AA8: 3 | AB8: 3 | AC8: 3 | AD8: 3 | AE8: 3 | AF8: 3 | AG8: 3 | AH8: 2 | AI8: 2 | AJ8: 2 | AK8: 2 | AL8: 2 | AM8: 2 | AN8: 2 | AO8: 3 | AP8: 3 | AR8: 0 | AS8: 14 | AT8: 16 | AU8: 0 | AV8: 0 | AW8: 0 | AX8: 0 | AY8: 0 | AZ8: 0 | BA8: 30 | CP8: 0 | CQ8: 0 | CR8: 0
A9: 8 | B9: 9850740-k | C9: 9850740 | D9: ARAYA | E9: TELLO | F9: JABIEL NICANOR | G9: MAESTRO PRIMERA GEOSINTETICOS | H9: 45992 | I9: D | J9: M | K9: 14X14 B | L9: 1790000090 | M9: 3 | N9: 3 | O9: 3 | P9: 3 | Q9: 3 | R9: 3 | S9: 3 | T9: 2 | U9: 2 | V9: 2 | W9: 2 | X9: 2 | Y9: 2 | Z9: 2 | AA9: 2 | AB9: 2 | AC9: 2 | AD9: 2 | AE9: 2 | AF9: 2 | AG9: 2 | AH9: 3 | AI9: 3 | AJ9: 3 | AK9: 3 | AL9: 3 | AM9: 3 | AN9: 3 | AO9: 3 | AP9: 3 | AR9: 0 | AS9: 14 | AT9: 16 | AU9: 0 | AV9: 0 | AW9: 0 | AX9: 0 | AY9: 0 | AZ9: 0 | BA9: 30 | BC9: 235333 | BD9: DESCANSO PENDIENTE POR CIERRE LABORAL AL 30-04-2026 | BP9: 75000 | CI9: 473333 | CP9: 0 | CQ9: 0 | CR9: 0
A10: 9 | B10: 9912965-4 | C10: 9912965 | D10: PEREZ | E10: OSSANDON | F10: ORIEL EDUARDO | G10: SUPERVISOR CONTROL CALIDAD | I10: I | J10: M | K10: 5X2 | L10: 1740000002 | M10: 9 | N10: 9 | O10: 9 | P10: 9 | Q10: 9 | R10: 9 | S10: 1 | T10: 1 | U10: 1 | V10: 1 | W10: 3 | X10: 3 | Y10: 9 | Z10: 9 | AA10: 9 | AB10: 9 | AC10: 9 | AD10: 9 | AE10: 9 | AF10: 9 | AG10: 9 | AH10: 9 | AI10: 9 | AJ10: 9 | AK10: 9 | AL10: 9 | AM10: 9 | AN10: 9 | AO10: 9 | AP10: 9 | AR10: 4 | AS10: 0 | AT10: 2 | AU10: 0 | AV10: 0 | AW10: 0 | AX10: 0 | AY10: 0 | AZ10: 24 | BA10: 30 | BE10: 519000 | BF10: Bono complemento sueldo | CH10: CENTRO DE COSTO (SIN FAENA) | CP10: 0 | CQ10: 0 | CR10: 0
A11: 10 | B11: 10147391-0 | C11: 10147391 | D11: SEGOVIA | E11: GUERRA | F11: PEDRO ENRIQUE | G11: AYUDANTE GEOSINTETICOS | H11: 45992 | I11: D | J11: M | K11: 14X14 B | L11: 1790000090 | M11: 3 | N11: 3 | O11: 3 | P11: 3 | Q11: 3 | R11: 3 | S11: 3 | T11: 2 | U11: 2 | V11: 2 | W11: 2 | X11: 2 | Y11: 2 | Z11: 2 | AA11: 2 | AB11: 2 | AC11: 2 | AD11: 2 | AE11: 2 | AF11: 2 | AG11: 2 | AH11: 3 | AI11: 3 | AJ11: 3 | AK11: 3 | AL11: 3 | AM11: 3 | AN11: 3 | AO11: 3 | AP11: 3 | AR11: 0 | AS11: 14 | AT11: 16 | AU11: 0 | AV11: 0 | AW11: 0 | AX11: 0 | AY11: 0 | AZ11: 0 | BA11: 30 | BC11: 130833 | BD11: DESCANSO PENDIENTE POR CIERRE LABORAL AL 30-04-2026 | BP11: 75000 | CI11: 473333 | CJ11: 213354 | CP11: 0 | CQ11: 0 | CR11: 0
A12: 11 | B12: 10192082-8 | C12: 10192082 | D12: GUERRERO | E12: GOMEZ | F12: LUIS HUMBERTO | G12: AYUDANTE GEOSINTETICOS | H12: 46096 | I12: D | J12: M | K12: 7X7 | L12: 1790000091 | M12: 3 | N12: 3 | O12: 3 | P12: 3 | Q12: 3 | R12: 3 | S12: 3 | T12: 2 | U12: 2 | V12: 2 | W12: 2 | X12: 2 | Y12: 2 | Z12: 2 | AA12: 3 | AB12: 3 | AC12: 3 | AD12: 3 | AE12: 3 | AF12: 3 | AG12: 3 | AH12: 2 | AI12: 2 | AJ12: 2 | AK12: 2 | AL12: 2 | AM12: 2 | AN12: 2 | AO12: 3 | AP12: 3 | AR12: 0 | AS12: 14 | AT12: 16 | AU12: 0 | AV12: 0 | AW12: 0 | AX12: 0 | AY12: 0 | AZ12: 0 | BA12: 30 | CP12: 0 | CQ12: 0 | CR12: 0
A13: 12 | B13: 10420797-9 | C13: 10420797 | D13: IRRIBARRA | E13: PEÑA | F13: HECTOR LEONIDAS | G13: JEFE RECURSOS HUMANOS PROYECTO | H13: 45704 | I13: I | J13: M | K13: 4X3 | L13: 1790000088 | M13: 1 | N13: 1 | O13: 3 | P13: 3 | Q13: 3 | R13: 1 | S13: 1 | T13: 1 | U13: 1 | V13: 3 | W13: 3 | X13: 3 | Y13: 1 | Z13: 1 | AA13: 1 | AB13: 1 | AC13: 3 | AD13: 3 | AE13: 3 | AF13: 1 | AG13: 1 | AH13: 1 | AI13: 1 | AJ13: 3 | AK13: 3 | AL13: 3 | AM13: 1 | AN13: 1 | AO13: 1 | AP13: 1 | AR13: 18 | AS13: 0 | AT13: 12 | AU13: 0 | AV13: 0 | AW13: 0 | AX13: 0 | AY13: 0 | AZ13: 0 | BA13: 30 | BM13: 0 | BY13: 61241 | CA13: 72000 | CB13: PAGO TRASLADO ALIMENTACION DIC-ENERO-ESPAÑA A TOKY EN EFECTIVO | CM13: 211065 | CP13: 0 | CQ13: 0 | CR13: 0
A14: 13 | B14: 10603186-K | C14: 10603186 | D14: LEON | E14: OLEA | F14: JAIME ANTONIO | G14: TECNICO RECURSOS HUMANOS PROYECTO | H14: 45748 | I14: I | J14: M | K14: A | L14: 1790000088 | M14: 1 | N14: 1 | O14: 3 | P14: 3 | Q14: 3 | R14: 1 | S14: 1 | T14: 1 | U14: 1 | V14: 3 | W14: 3 | X14: 3 | Y14: 1 | Z14: 1 | AA14: 1 | AB14: 1 | AC14: 3 | AD14: 3 | AE14: 3 | AF14: 1 | AG14: 1 | AH14: 1 | AI14: 1 | AJ14: 3 | AK14: 3 | AL14: 3 | AM14: 1 | AN14: 1 | AO14: 1 | AP14: 1 | AR14: 18 | AS14: 0 | AT14: 12 | AU14: 0 | AV14: 0 | AW14: 0 | AX14: 0 | AY14: 0 | AZ14: 0 | BA14: 30 | BE14: 300000 | BF14: Realizar actividades de ADMIN. CAMPAMENTO | BM14: 0 | CM14: 209667 | CP14: 0 | CQ14: 0 | CR14: 0
A15: 14 | B15: 10675506-K | C15: 10675506 | D15: CAMPILLAI | E15: NAVARRO | F15: VICTOR JAVIER | G15: JEFE DE UNIDAD LOGISTICA | I15: I | J15: M | K15: 5X2 | L15: 1740000003 | M15: 1 | N15: 1 | O15: 3 | P15: 3 | Q15: 3 | R15: 1 | S15: 1 | T15: 1 | U15: 1 | V15: 1 | W15: 3 | X15: 3 | Y15: 1 | Z15: 1 | AA15: 1 | AB15: 1 | AC15: 1 | AD15: 3 | AE15: 3 | AF15: 1 | AG15: 1 | AH15: 1 | AI15: 1 | AJ15: 1 | AK15: 3 | AL15: 3 | AM15: 1 | AN15: 1 | AO15: 1 | AP15: 1 | AR15: 21 | AS15: 0 | AT15: 9 | AU15: 0 | AV15: 0 | AW15: 0 | AX15: 0 | AY15: 0 | AZ15: 0 | BA15: 30 | BW15: 110000 | CP15: 0 | CQ15: =VLOOKUP(C15,SEGURO!$A$2:$C$28,3,0) -> 46667 | CR15: =VLOOKUP(C15,FALP!$A$2:$C$13,3,0) -> 17600
A16: 15 | B16: 10742396-6 | C16: 10742396 | D16: ALFARO | E16: CAMPUSANO | F16: EDUARDO ENRIQUE | G16: AYUDANTE GEOSINTETICOS | H16: 46068 | I16: D | J16: M | K16: 7X7 | L16: 1790000091 | M16: 3 | N16: 3 | O16: 3 | P16: 3 | Q16: 3 | R16: 3 | S16: 3 | T16: 2 | U16: 2 | V16: 2 | W16: 2 | X16: 2 | Y16: 2 | Z16: 2 | AA16: 3 | AB16: 3 | AC16: 3 | AD16: 3 | AE16: 3 | AF16: 3 | AG16: 3 | AH16: 2 | AI16: 2 | AJ16: 2 | AK16: 2 | AL16: 2 | AM16: 2 | AN16: 2 | AO16: 3 | AP16: 3 | AR16: 0 | AS16: 14 | AT16: 16 | AU16: 0 | AV16: 0 | AW16: 0 | AX16: 0 | AY16: 0 | AZ16: 0 | BA16: 30 | CP16: 0 | CQ16: 0 | CR16: 0
A17: 16 | B17: 10957493-7 | C17: 10957493 | D17: GONZALEZ | E17: QUINZACARA | F17: LUIS ARNOLDO | G17: CAPATAZ GEOSINTETICOS | H17: 45809 | I17: D | J17: M | K17: B | L17: 1790000088 | M17: 3 | N17: 3 | O17: 3 | P17: 3 | Q17: 3 | R17: 3 | S17: 1 | T17: 1 | U17: 2 | V17: 2 | W17: 2 | X17: 2 | Y17: 2 | Z17: 2 | AA17: 2 | AB17: 2 | AC17: 2 | AD17: 2 | AE17: 2 | AF17: 2 | AG17: 2 | AH17: 3 | AI17: 3 | AJ17: 3 | AK17: 3 | AL17: 3 | AM17: 3 | AN17: 3 | AO17: 3 | AP17: 3 | AR17: 2 | AS17: 13 | AT17: 15 | AU17: 0 | AV17: 0 | AW17: 0 | AX17: 0 | AY17: 0 | AZ17: 0 | BA17: 30 | BM17: 0 | CP17: 0 | CQ17: 0 | CR17: 0
A18: 17 | B18: 11265430-5 | C18: 11265430 | D18: FAUNDEZ | E18: ORTIZ | F18: CESAR HERNAN | G18: TOPÓGRAFO - NIVELADOR | H18: 45748 | I18: I | J18: M | K18: 4x3 | L18: 1790000088 | M18: 1 | N18: 1 | O18: 3 | P18: 3 | Q18: 3 | R18: 1 | S18: 1 | T18: 1 | U18: 1 | V18: 3 | W18: 3 | X18: 3 | Y18: 1 | Z18: 1 | AA18: 1 | AB18: 1 | AC18: 3 | AD18: 3 | AE18: 3 | AF18: 1 | AG18: 1 | AH18: 1 | AI18: 1 | AJ18: 3 | AK18: 3 | AL18: 3 | AM18: 1 | AN18: 1 | AO18: 1 | AP18: 1 | AR18: 18 | AS18: 0 | AT18: 12 | AU18: 0 | AV18: 0 | AW18: 0 | AX18: 0 | AY18: 0 | AZ18: 0 | BA18: 30 | BE18: 837000 | BF18: Bono asignacion de obra | BM18: 0 | CP18: 0 | CQ18: =VLOOKUP(C18,SEGURO!$A$2:$C$28,3,0) -> 45318 | CR18: 0
A19: 18 | B19: 11387365-5 | C19: 11387365 | D19: JOHNSON | E19: SUAZO | F19: CRISTIAN BENJAMIN | G19: CONDUCTOR SERVICIO | H19: 46082 | I19: I | J19: M | K19: 14X14 B | L19: 1790000090 | M19: 3 | N19: 3 | O19: 3 | P19: 3 | Q19: 3 | R19: 3 | S19: 3 | T19: 2 | U19: 2 | V19: 2 | W19: 2 | X19: 2 | Y19: 2 | Z19: 2 | AA19: 2 | AB19: 2 | AC19: 2 | AD19: 2 | AE19: 2 | AF19: 2 | AG19: 2 | AH19: 3 | AI19: 3 | AJ19: 3 | AK19: 3 | AL19: 3 | AM19: 3 | AN19: 3 | AO19: 3 | AP19: 3 | AR19: 0 | AS19: 14 | AT19: 16 | AU19: 0 | AV19: 0 | AW19: 0 | AX19: 0 | AY19: 0 | AZ19: 0 | BA19: 30 | BC19: 215000 | BD19: DESCANSO PENDIENTE POR CIERRE LABORAL AL 30-04-2026 | BP19: 75000 | BY19: 98114 | CI19: 315556 | CP19: 0 | CQ19: 0 | CR19: 0
A20: 19 | B20: 11511458-1 | C20: 11511458 | D20: ASTUDILLO | E20: FRE | F20: JUAN LUIS | G20: MAESTRO SEGUNDA GEOSINTETICOS | H20: 45992 | I20: D | J20: M | K20: 14x14 A | L20: 1790000090 | M20: 2 | N20: 2 | O20: 8 | P20: 8 | Q20: 2 | R20: 2 | S20: 2 | T20: 3 | U20: 3 | V20: 3 | W20: 3 | X20: 3 | Y20: 3 | Z20: 3 | AA20: 3 | AB20: 3 | AC20: 3 | AD20: 3 | AE20: 3 | AF20: 3 | AG20: 3 | AR20: 0 | AS20: 5 | AT20: 14 | AU20: 0 | AV20: 0 | AW20: 0 | AX20: 0 | AY20: 2 | AZ20: 0 | BA20: 21 | BM20: 2 | BN20: 180000 | BP20: 52500 | CI20: 315555 | CO20: =VLOOKUP(C20,'LOS HEROES'!$A$2:$D$30,4,0) -> 62330 | CP20: 0 | CQ20: 0 | CR20: 0
A21: 20 | B21: 11734191-7 | C21: 11734191 | D21: TORRES | E21: LOPEZ | F21: LUIS EDUARDO | G21: OPERADOR CAMIÓN PLUMA | H21: 45756 | I21: D | J21: M | K21: A | L21: 1790000088 | M21: 1 | N21: 1 | O21: 1 | P21: 1 | Q21: 1 | R21: 1 | S21: 1 | T21: 1 | U21: 1 | V21: 1 | W21: 1 | X21: 1 | Y21: 1 | Z21: 1 | AA21: 1 | AB21: 1 | AC21: 1 | AD21: 1 | AE21: 1 | AF21: 1 | AG21: 1 | AH21: 2 | AI21: 2 | AJ21: 2 | AK21: 2 | AL21: 2 | AM21: 2 | AN21: 2 | AO21: 2 | AP21: 2 | AR21: 21 | AS21: 9 | AT21: 0 | AU21: 0 | AV21: 0 | AW21: 0 | AX21: 0 | AY21: 0 | AZ21: 0 | BA21: 30 | BM21: 0 | CP21: 0 | CQ21: 0 | CR21: 0
A22: 21 | B22: 11820207-4 | C22: 11820207 | D22: MIRANDA | E22: CACERES | F22: HECTOR ANTONIO | G22: CAPATAZ GEOSINTETICOS | H22: 46092 | I22: D | J22: M | K22: 14X14 B | L22: 1790000090 | M22: 3 | N22: 3 | O22: 3 | P22: 3 | Q22: 3 | R22: 3 | S22: 3 | T22: 2 | U22: 2 | V22: 2 | W22: 2 | X22: 2 | Y22: 2 | Z22: 2 | AA22: 2 | AB22: 2 | AC22: 2 | AD22: 2 | AE22: 2 | AF22: 2 | AG22: 2 | AH22: 3 | AI22: 3 | AJ22: 3 | AK22: 3 | AL22: 3 | AM22: 3 | AN22: 3 | AO22: 3 | AP22: 3 | AR22: 0 | AS22: 14 | AT22: 16 | AU22: 0 | AV22: 0 | AW22: 0 | AX22: 0 | AY22: 0 | AZ22: 0 | BA22: 30 | BC22: 266667 | BD22: DESCANSO PENDIENTE POR CIERRE LABORAL AL 30-04-2026 | BK22: 160000 | BL22: 1 DIA ADICIONAL POR COUCHING EN ANTOFAGASTA | BP22: 75000 | BY22: 24000 | CI22: 157778 | CP22: 0 | CQ22: 0 | CR22: 0
A23: 22 | B23: 11876153-7 | C23: 11876153 | D23: HERNANDEZ | E23: DE LA FUENTE | F23: FERNANDO HIPOLITO | G23: SUPERVISRO VISITADOR E INSTRUCTOR | I23: I | J23: M | K23: 5X2 | L23: 1790000090 | M23: 1 | N23: 1 | O23: 3 | P23: 3 | Q23: 3 | R23: 1 | S23: 3 | T23: 3 | U23: 1 | V23: 1 | W23: 1 | X23: 1 | Y23: 1 | Z23: 3 | AA23: 3 | AB23: 1 | AC23: 1 | AD23: 1 | AE23: 1 | AF23: 1 | AG23: 3 | AH23: 3 | AI23: 1 | AJ23: 1 | AK23: 1 | AL23: 1 | AM23: 1 | AN23: 1 | AO23: 1 | AP23: 1 | AR23: 21 | AS23: 0 | AT23: 9 | AU23: 0 | AV23: 0 | AW23: 0 | AX23: 0 | AY23: 0 | AZ23: 0 | BA23: 30 | BW23: 110000 | CE23: 77281 | CO23: =VLOOKUP(C23,'LOS HEROES'!$A$2:$D$30,4,0) -> 451560 | CP23: 0 | CQ23: =VLOOKUP(C23,SEGURO!$A$2:$C$28,3,0) -> 46667 | CR23: =VLOOKUP(C23,FALP!$A$2:$C$13,3,0) -> 17600
A24: 23 | B24: 11922653-8 | C24: 11922653 | D24: ANDRADE | E24: CASTRO | F24: LUIS BERNARDO | G24: ENCARGADO DE MANTENCION | I24: I | J24: M | K24: 5X2 | L24: 1790000088 | M24: 4 | N24: 4 | O24: 4 | P24: 4 | Q24: 4 | R24: 4 | S24: 1 | T24: 1 | U24: 1 | V24: 1 | W24: 3 | X24: 3 | Y24: 1 | Z24: 1 | AA24: 1 | AB24: 1 | AC24: 1 | AD24: 3 | AE24: 3 | AF24: 1 | AG24: 1 | AH24: 1 | AI24: 1 | AJ24: 1 | AK24: 3 | AL24: 3 | AM24: 1 | AN24: 1 | AO24: 1 | AP24: 1 | AR24: 18 | AS24: 0 | AT24: 6 | AU24: 6 | AV24: 0 | AW24: 0 | AX24: 0 | AY24: 0 | AZ24: 0 | BA24: 24 | CO24: =VLOOKUP(C24,'LOS HEROES'!$A$2:$D$30,4,0) -> 309350 | CP24: 0 | CQ24: =VLOOKUP(C24,SEGURO!$A$2:$C$28,3,0) -> 32725 | CR24: 0
A25: 24 | B25: 12038137-7 | C25: 12038137 | D25: CORTES | E25: LÓPEZ | F25: MARCELO ANTONIO | G25: MAESTRO SEGUNDA GEOSINTETICOS | H25: 45924 | I25: D | J25: M | K25: B | L25: 1790000088 | M25: 1 | N25: 1 | O25: 1 | P25: 1 | Q25: 1 | R25: 1 | S25: 1 | T25: 1 | U25: 1 | V25: 1 | W25: 1 | AR25: 11 | AS25: 0 | AT25: 0 | AU25: 0 | AV25: 0 | AW25: 0 | AX25: 0 | AY25: 0 | AZ25: 0 | BA25: 11 | BM25: 0 | CP25: 0 | CQ25: 0 | CR25: 0
A26: 25 | B26: 12227004-1 | C26: 12227004 | D26: NARVAEZ | E26: PEÑA | F26: ALDO IVAN | G26: SUBGERENTE TECNICO | I26: I | J26: M | K26: 5X2 | L26: 1760000001 | M26: 1 | N26: 1 | O26: 3 | P26: 3 | Q26: 3 | R26: 1 | S26: 1 | T26: 1 | U26: 1 | V26: 1 | W26: 3 | X26: 3 | Y26: 1 | Z26: 1 | AA26: 1 | AB26: 1 | AC26: 1 | AD26: 3 | AE26: 3 | AF26: 1 | AG26: 1 | AH26: 1 | AI26: 1 | AJ26: 1 | AK26: 3 | AL26: 3 | AM26: 1 | AN26: 1 | AO26: 1 | AP26: 1 | AR26: 21 | AS26: 0 | AT26: 9 | AU26: 0 | AV26: 0 | AW26: 0 | AX26: 0 | AY26: 0 | AZ26: 0 | BA26: 30 | BE26: 179000 | BF26: Bono ajuste liquido pactado | CP26: 0 | CQ26: =VLOOKUP(C26,SEGURO!$A$2:$C$28,3,0) -> 32725 | CR26: =VLOOKUP(C26,FALP!$A$2:$C$13,3,0) -> 17600
A27: 26 | B27: 12397806-4 | C27: 12397806 | D27: RAMIREZ | E27: ORTEGA | F27: JUAN SIMON | G27: MAESTRO SEGUNDA GEOSINTETICOS | H27: 46064 | I27: D | J27: M | K27: 14X14 A | L27: 1790000090 | M27: 2 | N27: 2 | O27: 8 | P27: 8 | Q27: 2 | R27: 2 | S27: 2 | T27: 3 | U27: 3 | V27: 3 | W27: 3 | X27: 3 | Y27: 3 | Z27: 3 | AA27: 3 | AB27: 3 | AC27: 3 | AD27: 3 | AE27: 3 | AF27: 3 | AG27: 3 | AR27: 0 | AS27: 5 | AT27: 14 | AU27: 0 | AV27: 0 | AW27: 0 | AX27: 0 | AY27: 2 | AZ27: 0 | BA27: 21 | BM27: 2 | BN27: 180000 | BP27: 52500 | CI27: 157778 | CP27: 0 | CQ27: 0 | CR27: 0
A28: 27 | B28: 12443848-9 | C28: 12443848 | D28: MEDALLA | E28: CASTILLO | F28: MANUEL SEGUNDO | G28: AYUDANTE GEOSINTETICOS | H28: 46096 | I28: D | J28: M | K28: 7X7 | L28: 1790000091 | M28: 3 | N28: 3 | O28: 3 | P28: 3 | Q28: 3 | R28: 3 | S28: 3 | T28: 2 | U28: 2 | V28: 2 | W28: 2 | X28: 2 | Y28: 2 | Z28: 2 | AA28: 3 | AB28: 3 | AC28: 3 | AD28: 3 | AE28: 3 | AF28: 3 | AG28: 3 | AH28: 2 | AI28: 2 | AJ28: 2 | AK28: 2 | AL28: 2 | AM28: 2 | AN28: 2 | AO28: 3 | AP28: 3 | AR28: 0 | AS28: 14 | AT28: 16 | AU28: 0 | AV28: 0 | AW28: 0 | AX28: 0 | AY28: 0 | AZ28: 0 | BA28: 30 | CP28: 0 | CQ28: 0 | CR28: 0
A29: 28 | B29: 12487485-8 | C29: 12487485 | D29: SILVA | E29: BOCK | F29: DANIELA VIVIAN | G29: JEFE UNIDAD COMPENSACIONES | I29: I | J29: F | K29: 5X2 | L29: 1720000001 | M29: 1 | N29: 1 | O29: 3 | P29: 3 | Q29: 3 | R29: 1 | S29: 1 | T29: 1 | U29: 1 | V29: 1 | W29: 3 | X29: 3 | Y29: 1 | Z29: 1 | AA29: 1 | AB29: 1 | AC29: 9 | AD29: 3 | AE29: 3 | AF29: 1 | AG29: 1 | AH29: 1 | AI29: 1 | AJ29: 1 | AK29: 3 | AL29: 3 | AM29: 1 | AN29: 1 | AO29: 1 | AP29: 1 | AR29: 20 | AS29: 0 | AT29: 9 | AU29: 0 | AV29: 0 | AW29: 0 | AX29: 0 | AY29: 0 | AZ29: 1 | BA29: 30 | CP29: 0 | CQ29: =VLOOKUP(C29,SEGURO!$A$2:$C$28,3,0) -> 18779 | CR29: =VLOOKUP(C29,FALP!$A$2:$C$13,3,0) -> 17600
A30: 29 | B30: 12543039-2 | C30: 12543039 | D30: AVILA | E30: LINEROS | F30: AUDIAS ABDENEGO | G30: AYUDANTE GEOSINTETICOS | H30: 45995 | I30: D | J30: M | K30: 14X14 B | L30: 1790000090 | M30: 3 | N30: 3 | O30: 3 | P30: 3 | Q30: 3 | R30: 3 | S30: 3 | T30: 2 | U30: 2 | V30: 2 | W30: 2 | X30: 2 | Y30: 2 | Z30: 2 | AA30: 2 | AB30: 2 | AC30: 2 | AD30: 2 | AE30: 2 | AF30: 2 | AG30: 2 | AH30: 3 | AI30: 3 | AJ30: 3 | AK30: 3 | AL30: 3 | AM30: 3 | AN30: 3 | AO30: 3 | AP30: 3 | AR30: 0 | AS30: 14 | AT30: 16 | AU30: 0 | AV30: 0 | AW30: 0 | AX30: 0 | AY30: 0 | AZ30: 0 | BA30: 30 | BC30: 130833 | BD30: DESCANSO PENDIENTE POR CIERRE LABORAL AL 30-04-2026 | BP30: 75000 | BY30: 50900 | CI30: 473333 | CJ30: 213354 | CP30: 0 | CQ30: 0 | CR30: 0
A31: 30 | B31: 12572374-8 | C31: 12572374 | D31: PEREZ | E31: CARVAJAL | F31: ALBERTO HERNAN | G31: CONDUCTOR SERVICIO | H31: 46082 | I31: I | J31: M | K31: 14X14 A | L31: 1790000090 | M31: 2 | N31: 2 | O31: 8 | P31: 8 | Q31: 2 | R31: 2 | S31: 2 | T31: 3 | U31: 3 | V31: 3 | W31: 3 | X31: 3 | Y31: 3 | Z31: 3 | AA31: 3 | AB31: 3 | AC31: 3 | AD31: 3 | AE31: 3 | AF31: 3 | AG31: 3 | AR31: 0 | AS31: 5 | AT31: 14 | AU31: 0 | AV31: 0 | AW31: 0 | AX31: 0 | AY31: 2 | AZ31: 0 | BA31: 21 | BM31: 2 | BN31: 258000 | BP31: 52500 | CI31: 157778 | CP31: 0 | CQ31: 0 | CR31: 0
A32: 31 | B32: 12612919-k | C32: 12612919 | D32: HERRERA | E32: CORTES | F32: JUVENAL HUMBERTO | G32: AYUDANTE GEOSINTETICOS | H32: 45858 | I32: D | J32: M | K32: A | L32: 1790000088 | M32: 2 | N32: 2 | O32: 8 | P32: 8 | Q32: 2 | R32: 2 | S32: 2 | T32: 3 | U32: 3 | V32: 3 | W32: 3 | X32: 3 | Y32: 3 | Z32: 3 | AA32: 3 | AB32: 3 | AC32: 3 | AD32: 3 | AE32: 3 | AF32: 3 | AG32: 3 | AH32: 2 | AI32: 2 | AJ32: 2 | AK32: 2 | AL32: 2 | AM32: 2 | AN32: 2 | AO32: 2 | AP32: 2 | AR32: 0 | AS32: 14 | AT32: 14 | AU32: 0 | AV32: 0 | AW32: 0 | AX32: 0 | AY32: 2 | AZ32: 0 | BA32: 30 | BM32: 2 | BN32: 149200 | CP32: 0 | CQ32: 0 | CR32: 0
A33: 32 | B33: 12807347-7 | C33: 12807347 | D33: CORTES | E33: MONARDES | F33: PABLO ANTONIO | G33: MAESTRO SEGUNDA GEOSINTETICOS | H33: 46003 | I33: D | J33: M | K33: 14X14 B | L33: 1790000090 | M33: 3 | N33: 3 | O33: 3 | P33: 3 | Q33: 3 | R33: 3 | S33: 3 | T33: 2 | U33: 2 | V33: 2 | W33: 2 | X33: 2 | Y33: 2 | Z33: 2 | AA33: 2 | AB33: 2 | AC33: 2 | AD33: 2 | AE33: 2 | AF33: 2 | AG33: 2 | AH33: 3 | AI33: 3 | AJ33: 3 | AK33: 3 | AL33: 3 | AM33: 3 | AN33: 3 | AO33: 3 | AP33: 3 | AR33: 0 | AS33: 14 | AT33: 16 | AU33: 0 | AV33: 0 | AW33: 0 | AX33: 0 | AY33: 0 | AZ33: 0 | BA33: 30 | BC33: 150000 | BD33: DESCANSO PENDIENTE POR CIERRE LABORAL AL 30-04-2026 | BP33: 75000 | CI33: 473333 | CP33: 0 | CQ33: 0 | CR33: 0
A34: 33 | B34: 12943659-K | C34: 12943659 | D34: SANTANDER | E34: SANTANDER | F34: CARLOS LUIS | G34: SUPERVISOR GEOSINTETICOS | H34: 45992 | I34: I | J34: M | K34: 14x14 B | L34: 1790000090 | M34: 3 | N34: 3 | O34: 3 | P34: 3 | Q34: 3 | R34: 3 | S34: 3 | T34: 2 | U34: 2 | V34: 2 | W34: 2 | X34: 2 | Y34: 2 | Z34: 2 | AA34: 2 | AB34: 2 | AC34: 2 | AD34: 2 | AE34: 2 | AF34: 2 | AG34: 2 | AH34: 3 | AI34: 3 | AJ34: 3 | AK34: 3 | AL34: 3 | AM34: 3 | AN34: 3 | AO34: 3 | AP34: 3 | AR34: 0 | AS34: 14 | AT34: 16 | AU34: 0 | AV34: 0 | AW34: 0 | AX34: 0 | AY34: 0 | AZ34: 0 | BA34: 30 | BC34: 428833 | BD34: DESCANSO PENDIENTE POR CIERRE LABORAL AL 30-04-2026 | BE34: 860000 | BF34: Bono acuerdo salarial | BK34: 257300 | BL34: 1 DIA ADICIONAL POR COUCHING EN ANTOFAGASTA | CE34: 77281 | CI34: 473333 | CO34: =VLOOKUP(C34,'LOS HEROES'!$A$2:$D$30,4,0) -> 290002 | CP34: 0 | CQ34: 0 | CR34: 0
A35: 34 | B35: 12953191-6 | C35: 12953191 | D35: ARELLANO | E35: ARRIAZA | F35: MARCO ANTONIO | G35: TECNICO RRHH PROYECTO | H35: 45971 | I35: D | J35: M | K35: 14x14 D | L35: 1790000090 | M35: 3 | N35: 3 | O35: 3 | P35: 3 | Q35: 3 | R35: 3 | S35: 3 | T35: 3 | U35: 3 | V35: 3 | W35: 3 | X35: 3 | Y35: 3 | Z35: 3 | AA35: 2 | AB35: 2 | AC35: 2 | AD35: 2 | AE35: 2 | AF35: 2 | AG35: 2 | AH35: 2 | AI35: 2 | AJ35: 2 | AK35: 2 | AL35: 2 | AM35: 2 | AN35: 2 | AO35: 3 | AP35: 3 | AR35: 0 | AS35: 14 | AT35: 16 | AU35: 0 | AV35: 0 | AW35: 0 | AX35: 0 | AY35: 0 | AZ35: 0 | BA35: 30 | BC35: 620000 | BD35: DESCANSO PENDIENTE POR CIERRE LABORAL AL 30-04-2026 | BP35: 75000 | BY35: 31000 | CI35: 473333 | CP35: 0 | CQ35: 0 | CR35: 0
A36: 35 | B36: 13012039-3 | C36: 13012039 | D36: LOBOS | E36: PIZARRO | F36: JORGE HUMBERTO | G36: JEFE CONTROL DE CALIDAD | H36: 46118 | I36: I | J36: M | K36: 5X2 | L36: 1790000088 | R36: 1 | S36: 1 | T36: 1 | U36: 1 | V36: 1 | W36: 3 | X36: 3 | Y36: 1 | Z36: 1 | AA36: 1 | AB36: 1 | AC36: 1 | AD36: 3 | AE36: 3 | AF36: 1 | AG36: 1 | AH36: 1 | AI36: 1 | AJ36: 1 | AK36: 3 | AL36: 3 | AM36: 1 | AN36: 1 | AO36: 1 | AP36: 1 | AR36: 19 | AS36: 0 | AT36: 6 | AU36: 0 | AV36: 0 | AW36: 0 | AX36: 0 | AY36: 0 | AZ36: 0 | BA36: 25 | CP36: 0 | CQ36: 0 | CR36: 0
A37: 36 | B37: 13076470-3 | C37: 13076470 | D37: REHBEIN | E37: GANTES | F37: ANTONIO ALEJANDRO | G37: JEFE DE TERRENO | H37: 45805 | I37: I | J37: M | K37: B | L37: 1790000088 | M37: 3 | N37: 3 | O37: 3 | P37: 3 | Q37: 3 | R37: 3 | S37: 3 | T37: 2 | U37: 2 | V37: 2 | W37: 2 | X37: 2 | Y37: 1 | Z37: 1 | AA37: 2 | AB37: 2 | AC37: 2 | AD37: 2 | AE37: 2 | AF37: 2 | AG37: 2 | AH37: 3 | AI37: 3 | AJ37: 3 | AK37: 3 | AL37: 3 | AM37: 3 | AN37: 3 | AO37: 3 | AP37: 3 | AR37: 2 | AS37: 12 | AT37: 16 | AU37: 0 | AV37: 0 | AW37: 0 | AX37: 0 | AY37: 0 | AZ37: 0 | BA37: 30 | BE37: 375000 | BF37: Bono ajuste salarial | BM37: 0 | CP37: 0 | CQ37: 0 | CR37: 0
A38: 37 | B38: 13172993-6 | C38: 13172993 | D38: GODOY | E38: CORTES | F38: SANDRA ROSARIO | G38: ADMINISTRATIVO OFICINA TECNICA | H38: 45839 | I38: I | J38: F | K38: 4X3 | L38: 1790000088 | M38: 1 | N38: 3 | O38: 3 | P38: 3 | AR38: 1 | AS38: 0 | AT38: 3 | AU38: 0 | AV38: 0 | AW38: 0 | AX38: 0 | AY38: 0 | AZ38: 0 | BA38: 4 | BM38: 0 | CP38: 0 | CQ38: 0 | CR38: 0
A39: 38 | B39: 13174740-3 | C39: 13174740 | D39: ROJAS | E39: GERALDO | F39: EUGENIO DAVID | G39: MAESTRO SEGUNDA GEOSINTETICOS | H39: 45846 | I39: D | J39: M | K39: B | L39: 1790000088 | M39: 3 | N39: 3 | O39: 3 | P39: 3 | Q39: 3 | R39: 3 | S39: 3 | T39: 2 | U39: 2 | V39: 2 | W39: 2 | X39: 2 | Y39: 2 | Z39: 2 | AA39: 2 | AB39: 2 | AC39: 2 | AD39: 2 | AE39: 2 | AF39: 2 | AG39: 2 | AH39: 3 | AI39: 3 | AJ39: 3 | AK39: 3 | AL39: 3 | AM39: 3 | AN39: 3 | AO39: 3 | AP39: 3 | AR39: 0 | AS39: 14 | AT39: 16 | AU39: 0 | AV39: 0 | AW39: 0 | AX39: 0 | AY39: 0 | AZ39: 0 | BA39: 30 | BM39: 0 | CP39: 0 | CQ39: 0 | CR39: 0
A40: 39 | B40: 13179077-5 | C40: 13179077 | D40: GUERRERO | E40: GARCÍA | F40: PEDRO FREDDY | G40: JEFE PREVENCION DE RIESGOS | H40: 45957 | I40: I | J40: M | K40: 4X3 | L40: 1790000090 | M40: 2 | N40: 2 | O40: 3 | P40: 3 | Q40: 3 | R40: 2 | S40: 2 | T40: 2 | U40: 2 | V40: 3 | W40: 3 | X40: 3 | Y40: 2 | Z40: 2 | AA40: 2 | AB40: 2 | AC40: 3 | AD40: 3 | AE40: 3 | AF40: 2 | AG40: 2 | AH40: 2 | AI40: 2 | AJ40: 3 | AK40: 3 | AL40: 3 | AM40: 2 | AN40: 2 | AO40: 2 | AP40: 2 | AR40: 0 | AS40: 18 | AT40: 12 | AU40: 0 | AV40: 0 | AW40: 0 | AX40: 0 | AY40: 0 | AZ40: 0 | BA40: 30 | BC40: 333600 | BD40: DIA ADICIONAL PENDIENTE POR REEMPLAZO DE APR (M. IBARRA) | BY40: 120050 | CI40: 473333 | CK40: 1000800 | CL40: 100000 | CP40: 0 | CQ40: 0 | CR40: 0
...

Sheet LOS HEROES
A1: Rut Trabajador | B1: DV RUT | C1: Nombre del Trabajador | D1: Valor Cuota
A2: 7365743 | B2: 1 | C2: BONE SANTIS CARLOS ALBERTO | D2: 552163
A3: 9430404 | B3: 0 | C3: BARRIA BARRIENTOS HARRY ISMAEL | D3: 64673
A4: 9583446 | B4: 9 | C4: CARJA JARA CRESCENTE ARTURO | D4: 46152
A5: 9717041 | B5: K | C5: OLIVARES DIAZ GONZALO LUIS | D5: 100429
A6: 11511458 | B6: 1 | C6: ASTUDILLO FRE JUAN LUIS | D6: 62330
A7: 11876153 | B7: 7 | C7: HERNANDEZ DE LA FUENTE FERNANDO HIPOLIT | D7: 451560
A8: 11922653 | B8: 8 | C8: ANDRADE CASTRO LUIS BERNARDO | D8: 309350
A9: 12713498 | B9: 7 | C9: ENIPANE CANOBRA RENE | D9: 19252
A10: 12943659 | B10: K | C10: SANTANDER SANTANDER CARLOS LUIS | D10: 290002
A11: 13205525 | B11: 4 | C11: ORTIZ MEDEL SEBASTIAN DEL CARMEN | D11: 343828
A12: 14296775 | B12: 8 | C12: CORTES HINAREJO ALEXIS RODRIGO | D12: 388170
A13: 15050650 | B13: 6 | C13: CODOCEO ORMENO JOEL ALEXANDER | D13: 184089
A14: 15164558 | B14: 5 | C14: SEPULVEDA VARGAS ESTEBAN ANDRES | D14: 250278
A15: 15373866 | B15: 1 | C15: ESTAY MORALES RENE ORLANDO | D15: 26705
A16: 15802017 | B16: 3 | C16: ARGANDONA IBACACHE PABLO CESAR | D16: 154145
A17: 16109258 | B17: 4 | C17: JOSE ORLANDO VALDERRAMA TABILO | D17: 5522
A18: 16596546 | B18: 9 | C18: GALLEGUILLOS GALLEGUILLOS WALDO GABRIEL | D18: 39152
A19: 16911975 | B19: 9 | C19: DIAZ GUAJARDO KATHERINE VALESKA | D19: 323598
A20: 17164817 | B20: 3 | C20: HERRERA CARVALLO FANNY DENIS | D20: 445677
A21: 17887975 | B21: 8 | C21: PIZARRO VEGA CRISTIAN FERNANDO | D21: 170812
A22: 18193913 | B22: 3 | C22: JOSE MIGUEL CALDERON ALVAREZ | D22: 5522
A23: 18217453 | B23: K | C23: PASTEN GUZMAN JAIRO BRAYAN | D23: 73099
A24: 18353315 | B24: 0 | C24: SEGOVIA ALFARO FABIAN EDGARDO | D24: 172524
A25: 19302584 | B25: 6 | C25: CASTILLO RODRIGUEZ JONATHAN ALEXANDER | D25: 197253
A26: 19467130 | B26: K | C26: IVAN MARCELO VILLEGAS CARMONA | D26: 5522
A27: 19496318 | B27: 1 | C27: GUERRERO LOPEZ CRISTOFHER ANDRES | D27: 63000
A28: 20051179 | B28: 4 | C28: PATRICIO ANDRES HIDALGO SEGOVIA | D28: 5522
A29: 20494956 | B29: 5 | C29: JOSE IGNACIO BARAHONA BERRIOS | D29: 5522
A30: 20866663 | B30: 0 | C30: ALVARO ALFONSO EXEQUIEL PEREZ ROJAS | D30: 5522

Sheet LA ARAUCANA
A1: RutAfiliado | B1: DvAfiliado | C1: NombreAfiliado | D1: MontoCuotaPendiente
A2: 13327527 | B2: 4 | C2: VICTOR POBLETE | D2: 154868
A3: 8532533 | B3: 7 | C3: ALEJANDRO ELGUETA | D3: 176117
A4: 15876024 | B4: K | C4: MANUEL STUARDO | D4: 101408
A5: 10904003 | B5: 7 | C5: DAVID EXEQUIEL | D5: 116803

Sheet SEGURO
A1: RUT | B1: TOTAL | C1: 0.3
A2: 10675506 | B2: 155558 | C2: 46667
A3: 11265430 | B3: 151060 | C3: 45318
A4: 11876153 | B4: 155558 | C4: 46667
A5: 11922653 | B5: 109083 | C5: 32725
A6: 12227004 | B6: 109083 | C6: 32725
A7: 12487485 | B7: 62596 | C7: 18779
A8: 13419327 | B8: 155558 | C8: 46667
A9: 13531208 | B9: 155558 | C9: 46667
A10: 13702938 | B10: 155558 | C10: 46667
A11: 13904453 | B11: 155558 | C11: 46667
A12: 14113613 | B12: 155558 | C12: 46667
A13: 14129064 | B13: 155558 | C13: 46667
... A28: 13531208 | B28: 155558 | C28: 46667

Sheet FALP
A1: R.U.T. | B1: Nombre | C1: Total
A2: 14129064 | B2: DIAZ BASUALTO, ANDRES | C2: 17600
A3: 15661268 | B3: REBOLLEDO ROSALES, LUIS | C3: 17600
A4: 13531208 | B4: ARAYA REYES, MARCO | C4: 17600
A5: 15936945 | B5: SEPULVEDA VERGAR, KARLA | C5: 8800
A6: 17164817 | B6: HERRERA CARVALLO, FANNY DENIS | C6: 8800
A7: 11876153 | B7: HERNANDEZ DE LA FUENTE, FERNANDO | C7: 17600
A8: 12227004 | B8: NARVAEZ PEÑA, ALDO | C8: 17600
A9: 10675506 | B9: CAMPILLAI NAVARRO, VICTOR | C9: 17600
A10: 17119888 | B10: LABRA RAMIREZ, JANITZA ANABAENA | C10: 17600
A11: 13904453 | B11: TORO ANDRADE, ESTEBAN | C11: 8800
A12: 8077970 | B12: RETAMAL ARAYA, JAIME LORENZO | C12: 17600
A13: 12487485 | B13: SILVA BOCK, DANIELA | C13: 17600

Sheet 04_2026_OF
A1: Nº | B1: RUT (sin puntos y con guion) | C1: ID (rut sin puntos, sin guión ni digito vertificador) | D1: APELLIDO PATERNO | E1: APELLIDO MATERNO | F1: NOMBRES | G1: CARGO | H1: INICIO DE CONTRATO | I1: D/I | J1: GENERO M/F | K1: TURNO (5x2-4x3-14x14 -art22) | L1: CC | M1: 1 | N1: 2 | O1: 3 | P1: 4 | Q1: 5 | R1: 6 | S1: 7 | T1: 8 | U1: 9 | V1: 10 | W1: 11 | X1: 12 | Y1: 13 | Z1: 14 | AA1: 15 | AB1: 16 | AC1: 17 | AD1: 18 | AE1: 19 | AF1: 20 | AG1: 21 | AH1: 22 | AI1: 23 | AJ1: 24 | AK1: 25 | AL1: 26 | AM1: 27 | AN1: 28 | AO1: 29 | AP1: 30 | AQ1: 31 | AR1: (1) | AS1: (2) | AT1: (3) | AU1: (4) | AV1: (5) | AW1: (6) | AX1: (7) | AY1: (8) | AZ1: (9) | BA1: T.D.T. | BB1: 1033-Bono Gestión Variable | BC1: 1029-Bono Compensatorio descanso | BD1: Justificación Bono 10-29 (Compensatorio descanso) | BE1: 1034-Bono Incentivo variable | BF1: Justificación Bono 1034 (Incentivo variable) | BG1: 1140-Bono Responsabilidad 2 | BH1: Justificación 1140 (Bono Responsabilidad) | BI1: 1041-Bono Terreno (Exclusivo proyecto Techint-CMDIC) | BJ1: 1031-Bono Escolaridad I/T (Uso exclusivo Area de Compensaciones) | BK1: 1092-Diferencia de haber | BL1: Justificación Bono 1092 (Diferencia de Haber) | BM1: Cantidad de feriados del mes | BN1: 1082-Bono Compens. Feriado | BO1: 1020-Aguinaldo I/T | BP1: 1140-Bono de Permanencia (Plan de Beneficios) | BQ1: Bono Seguridad BESALCO-MEL | BR1: Bono Q1 (Exclusivo Collahuasi) | BS1: Bono Q2 (Exclusivo Collahuasi) | BT1: Bono Q3 (Exclusivo Collahuasi) | BU1: Bono Q4 (Exclusivo Collahuasi) | BV1: Bono RSA (Exclusivo Collahuasi) | BW1: 1044-Asignación Colación | BX1: Justificación Asignacion Colacion | BY1: 1165-Asignación Movilización 2 | BZ1: Justificación Asignación Movilización 2 | CA1: 1172-Viatico 2 | CB1: Justificación Viatico | CC1: 1073-Otras Asignaciones N/I (Beneficios) | CD1: Justificaciión de Asignación (Detalle del beneficio) | CE1: 1032-Bono Escolaridad N/I | CF1: 1124-Asignación familiar Retroactiva | CG1: Descuento por aporte voluntario | CH1: Observaciones generales | CI1: ACUERDO MARCO ACCIONA-CODELCO | CJ1: GRATIFICACION ACUERD MARCO ACCIONA-CODELCO2 | CK1: DIAS ADICIONALES CHIQUICAMATA | CL1: BONO PARTICIPACION CHIQUI
A2: 1 | B2: 7365743-1 | C2: 7365743 | D2: BONE | E2: SANTIS | F2: CARLOS ALBERTO | G2: GERENTE GENERAL | I2: I | J2: M | K2: 5X2 | L2: 1710000001 | M2: 1 | N2: 1 | O2: 3 | P2: 3 | Q2: 3 | R2: 1 | S2: 1 | T2: 1 | U2: 1 | V2: 1 | W2: 3 | X2: 3 | Y2: 1 | Z2: 1 | AA2: 1 | AB2: 1 | AC2: 1 | AD2: 3 | AE2: 3 | AF2: 1 | AG2: 1 | AH2: 1 | AI2: 1 | AJ2: 1 | AK2: 3 | AL2: 3 | AM2: 1 | AN2: 1 | AO2: 1 | AP2: 1 | AR2: 21 | AS2: 0 | AT2: 9 | AU2: 0 | AV2: 0 | AW2: 0 | AX2: 0 | AY2: 0 | AZ2: 0 | BA2: 30
A3: 2 | B3: 9205219-2 | C3: 9205219 | D3: JOGLAR | E3: ZAMBRANA | F3: ADOLFO | G3: GERENTE GESTION PERSONAS | I3: I | J3: M | K3: 5X2 | L3: 1720000001 | M3: 1 | N3: 1 | O3: 3 | P3: 3 | Q3: 3 | R3: 1 | S3: 1 | T3: 1 | U3: 1 | V3: 3 | W3: 3 | X3: 3 | Y3: 1 | Z3: 1 | AA3: 1 | AB3: 1 | AC3: 3 | AD3: 3 | AE3: 3 | AF3: 1 | AG3: 1 | AH3: 1 | AI3: 1 | AJ3: 3 | AK3: 3 | AL3: 3 | AM3: 1 | AN3: 1 | AO3: 1 | AP3: 1 | AR3: 18 | AS3: 0 | AT3: 12 | AU3: 0 | AV3: 0 | AW3: 0 | AX3: 0 | AY3: 0 | AZ3: 0 | BA3: 30
A4: 3 | B4: 9430404-0 | C4: 9430404 | D4: BARRIA | E4: BARRIENTOS | F4: HARRY ISMAEL | G4: ENCARGADO TALLER MANTENCION | I4: I | J4: M | K4: 5X2 | L4: 1740000002 | M4: 1 | N4: 1 | O4: 3 | P4: 3 | Q4: 3 | R4: 9 | S4: 9 | T4: 9 | U4: 9 | V4: 9 | W4: 9 | X4: 9 | Y4: 9 | Z4: 9 | AA4: 9 | AB4: 9 | AC4: 9 | AD4: 9 | AE4: 9 | AF4: 1 | AG4: 1 | AH4: 1 | AI4: 1 | AJ4: 1 | AK4: 3 | AL4: 3 | AM4: 1 | AN4: 1 | AO4: 1 | AP4: 1 | AR4: 11 | AS4: 0 | AT4: 5 | AU4: 0 | AV4: 0 | AW4: 0 | AX4: 0 | AY4: 0 | AZ4: 14 | BA4: 30 | CA4: 30000 | CB4: Viatico para traslado terminal buses oficina (4 am)
A5: 4 | B5: 10675506-K | C5: 10675506 | D5: CAMPILLAI | E5: NAVARRO | F5: VICTOR JAVIER | G5: JEFE DE UNIDAD LOGISTICA | I5: I | J5: M | K5: 5X2 | L5: 1740000003 | M5: 1 | N5: 1 | O5: 3 | P5: 3 | Q5: 3 | R5: 1 | S5: 1 | T5: 1 | U5: 1 | V5: 1 | W5: 3 | X5: 3 | Y5: 1 | Z5: 1 | AA5: 1 | AB5: 1 | AC5: 1 | AD5: 3 | AE5: 3 | AF5: 1 | AG5: 1 | AH5: 1 | AI5: 1 | AJ5: 1 | AK5: 3 | AL5: 3 | AM5: 1 | AN5: 1 | AO5: 1 | AP5: 1 | AR5: 21 | AS5: 0 | AT5: 9 | AU5: 0 | AV5: 0 | AW5: 0 | AX5: 0 | AY5: 0 | AZ5: 0 | BA5: 30 | BW5: 110000
A6: 5 | B6: 12227004-1 | C6: 12227004 | D6: NARVAEZ | E6: PEÑA | F6: ALDO IVAN | G6: SUBGERENTE TECNICO | I6: I | J6: M | K6: 5X2 | L6: 1760000001 | M6: 1 | N6: 1 | O6: 3 | P6: 3 | Q6: 3 | R6: 1 | S6: 1 | T6: 1 | U6: 1 | V6: 1 | W6: 3 | X6: 3 | Y6: 1 | Z6: 1 | AA6: 1 | AB6: 1 | AC6: 1 | AD6: 3 | AE6: 3 | AF6: 1 | AG6: 1 | AH6: 1 | AI6: 1 | AJ6: 1 | AK6: 3 | AL6: 3 | AM6: 1 | AN6: 1 | AO6: 1 | AP6: 1 | AR6: 21 | AS6: 0 | AT6: 9 | AU6: 0 | AV6: 0 | AW6: 0 | AX6: 0 | AY6: 0 | AZ6: 0 | BA6: 30 | BE6: 179000 | BF6: Bono ajuste liquido pactado
A7: 6 | B7: 12487485-8 | C7: 12487485 | D7: SILVA | E7: BOCK | F7: DANIELA VIVIAN | G7: JEFE UNIDAD COMPENSACIONES | I7: I | J7: F | K7: 5X2 | L7: 1720000001 | M7: 1 | N7: 1 | O7: 3 | P7: 3 | Q7: 3 | R7: 1 | S7: 1 | T7: 1 | U7: 1 | V7: 1 | W7: 3 | X7: 3 | Y7: 1 | Z7: 1 | AA7: 1 | AB7: 1 | AC7: 9 | AD7: 3 | AE7: 3 | AF7: 1 | AG7: 1 | AH7: 1 | AI7: 1 | AJ7: 1 | AK7: 3 | AL7: 3 | AM7: 1 | AN7: 1 | AO7: 1 | AP7: 1 | AR7: 20 | AS7: 0 | AT7: 9 | AU7: 0 | AV7: 0 | AW7: 0 | AX7: 0 | AY7: 0 | AZ7: 1 | BA7: 30
A8: 7 | B8: 13904453-3 | C8: 13904453 | D8: TORO | E8: ANDRADE | F8: ESTEBAN | G8: GERENTE DE PLANIFICACION Y CONTROL | I8: I | J8: M | K8: 5X2 | L8: 1740000001 | M8: 1 | N8: 1 | O8: 3 | P8: 3 | Q8: 3 | R8: 1 | S8: 1 | T8: 1 | U8: 1 | V8: 1 | W8: 3 | X8: 3 | Y8: 1 | Z8: 1 | AA8: 1 | AB8: 1 | AC8: 1 | AD8: 3 | AE8: 3 | AF8: 1 | AG8: 1 | AH8: 1 | AI8: 1 | AJ8: 1 | AK8: 3 | AL8: 3 | AM8: 1 | AN8: 1 | AO8: 1 | AP8: 1 | AR8: 21 | AS8: 0 | AT8: 9 | AU8: 0 | AV8: 0 | AW8: 0 | AX8: 0 | AY8: 0 | AZ8: 0 | BA8: 30
A9: 8 | B9: 14113613-5 | C9: 14113613 | D9: BARRIOS | E9: ACUÑA | F9: NELSON ENRIQUE | G9: JEFE GESTION PERSONAS | I9: I | J9: M | K9: 5X2 | L9: 1740000001 | M9: 1 | N9: 1 | O9: 3 | P9: 3 | Q9: 3 | R9: 1 | S9: 1 | T9: 1 | U9: 1 | V9: 1 | W9: 3 | X9: 3 | Y9: 1 | Z9: 1 | AA9: 1 | AB9: 1 | AC9: 1 | AD9: 3 | AE9: 3 | AF9: 1 | AG9: 1 | AH9: 1 | AI9: 1 | AJ9: 1 | AK9: 3 | AL9: 3 | AM9: 1 | AN9: 1 | AO9: 1 | AP9: 1 | AR9: 21 | AS9: 0 | AT9: 9 | AU9: 0 | AV9: 0 | AW9: 0 | AX9: 0 | AY9: 0 | AZ9: 0 | BA9: 30
A10: 9 | B10: 14129064-9 | C10: 14129064 | D10: DIAZ | E10: BASOALTO | F10: ANDRES EDUARDO | G10: SUBGERENTE DE CONTABILIDAD Y FINANZAS | I10: I | J10: M | K10: 5X2 | L10: 1720000002 | M10: 1 | N10: 1 | O10: 3 | P10: 3 | Q10: 3 | R10: 1 | S10: 1 | T10: 1 | U10: 1 | V10: 1 | W10: 3 | X10: 3 | Y10: 1 | Z10: 1 | AA10: 1 | AB10: 1 | AC10: 1 | AD10: 3 | AE10: 3 | AF10: 1 | AG10: 1 | AH10: 1 | AI10: 1 | AJ10: 1 | AK10: 3 | AL10: 3 | AM10: 1 | AN10: 1 | AO10: 1 | AP10: 1 | AR10: 21 | AS10: 0 | AT10: 9 | AU10: 0 | AV10: 0 | AW10: 0 | AX10: 0 | AY10: 0 | AZ10: 0 | BA10: 30
A11: 10 | B11: 15661268-5 | C11: 15661268 | D11: REBOLLEDO | E11: ROSALES | F11: LUIS ANDRES | G11: INGENIERO DE PROYECTOS | I11: I | J11: M | K11: 5X2 | L11: 1750000001 | M11: 1 | N11: 1 | O11: 3 | P11: 3 | Q11: 3 | R11: 1 | S11: 1 | T11: 1 | U11: 1 | V11: 1 | W11: 1 | X11: 1 | Y11: 1 | Z11: 1 | AA11: 1 | AB11: 1 | AC11: 1 | AD11: 3 | AE11: 3 | AF11: 1 | AG11: 1 | AH11: 1 | AI11: 1 | AJ11: 1 | AK11: 3 | AL11: 3 | AM11: 1 | AN11: 1 | AO11: 1 | AP11: 1 | AR11: 23 | AS11: 0 | AT11: 7 | AU11: 0 | AV11: 0 | AW11: 0 | AX11: 0 | AY11: 0 | AZ11: 0 | BA11: 30
A12: 11 | B12: 15936945-5 | C12: 15936945 | D12: SEPULVEDA | E12: VERGARA | F12: KARLA ANDREA | G12: SUBGERENTE DE ESTUDIO DE PROYECTOS | I12: I | J12: F | K12: 5X2 | L12: 1750000001 | M12: 1 | N12: 1 | O12: 3 | P12: 3 | Q12: 3 | R12: 1 | S12: 1 | T12: 1 | U12: 1 | V12: 1 | W12: 3 | X12: 3 | Y12: 1 | Z12: 1 | AA12: 1 | AB12: 1 | AC12: 1 | AD12: 3 | AE12: 3 | AF12: 1 | AG12: 1 | AH12: 1 | AI12: 1 | AJ12: 1 | AK12: 3 | AL12: 3 | AM12: 1 | AN12: 1 | AO12: 1 | AP12: 1 | AR12: 21 | AS12: 0 | AT12: 9 | AU12: 0 | AV12: 0 | AW12: 0 | AX12: 0 | AY12: 0 | AZ12: 0 | BA12: 30
A13: 12 | B13: 16481993-0 | C13: 16481993 | D13: GOLOTT | E13: VALDES | F13: MARIA JOSE IGNACIA | G13: CONDUCTOR CAMION RAMPA | I13: D | J13: F | K13: 5X2 | L13: 1740000002 | M13: 1 | N13: 1 | O13: 3 | P13: 3 | Q13: 3 | R13: 1 | S13: 1 | T13: 1 | U13: 1 | V13: 1 | W13: 3 | X13: 3 | Y13: 1 | Z13: 1 | AA13: 1 | AB13: 1 | AC13: 1 | AD13: 3 | AE13: 3 | AF13: 1 | AG13: 1 | AH13: 1 | AI13: 1 | AJ13: 1 | AK13: 3 | AL13: 3 | AM13: 1 | AN13: 1 | AO13: 1 | AP13: 1 | AR13: 21 | AS13: 0 | AT13: 9 | AU13: 0 | AV13: 0 | AW13: 0 | AX13: 0 | AY13: 0 | AZ13: 0 | BA13: 30
A14: 13 | B14: 16911975-9 | C14: 16911975 | D14: DIAZ | E14: GUAJARDO | F14: KATHRINE VALESKA | G14: ENCARGADA DOCUMENTAL DE DESPACHOS | I14: I | J14: F | K14: 5X2 | L14: 1720000002 | M14: 1 | N14: 1 | O14: 3 | P14: 3 | Q14: 3 | R14: 1 | S14: 1 | T14: 1 | U14: 1 | V14: 1 | W14: 3 | X14: 3 | Y14: 1 | Z14: 1 | AA14: 1 | AB14: 1 | AC14: 1 | AD14: 3 | AE14: 3 | AF14: 1 | AG14: 1 | AH14: 1 | AI14: 1 | AJ14: 1 | AK14: 3 | AL14: 3 | AM14: 1 | AN14: 1 | AO14: 1 | AP14: 1 | AR14: 21 | AS14: 0 | AT14: 9 | AU14: 0 | AV14: 0 | AW14: 0 | AX14: 0 | AY14: 0 | AZ14: 0 | BA14: 30
A15: 14 | B15: 17119888-7 | C15: 17119888 | D15: LABRA | E15: RAMIREZ | F15: JANITZA ANABAENA | G15: ENCARGADA DOCUMENTAL Y CONTROL DE GESTION | I15: I | J15: F | K15: 5X2 | L15: 1740000001 | M15: 1 | N15: 1 | O15: 3 | P15: 3 | Q15: 3 | R15: 1 | S15: 1 | T15: 1 | U15: 1 | V15: 1 | W15: 3 | X15: 3 | Y15: 1 | Z15: 1 | AA15: 1 | AB15: 1 | AC15: 1 | AD15: 3 | AE15: 3 | AF15: 1 | AG15: 1 | AH15: 1 | AI15: 1 | AJ15: 1 | AK15: 3 | AL15: 3 | AM15: 1 | AN15: 1 | AO15: 1 | AP15: 1 | AR15: 21 | AS15: 0 | AT15: 9 | AU15: 0 | AV15: 0 | AW15: 0 | AX15: 0 | AY15: 0 | AZ15: 0 | BA15: 30
A16: 15 | B16: 17164817-3 | C16: 17164817 | D16: HERRERA | E16: CARVALLO | F16: FANNY DENIS | G16: ENCARGADA SSOMAC | I16: I | J16: F | K16: 5X2 | L16: 1740000001 | M16: 1 | N16: 1 | O16: 3 | P16: 3 | Q16: 3 | R16: 1 | S16: 1 | T16: 4 | U16: 4 | V16: 4 | W16: 4 | X16: 4 | Y16: 4 | Z16: 4 | AA16: 4 | AB16: 4 | AC16: 4 | AD16: 4 | AE16: 4 | AF16: 4 | AG16: 4 | AH16: 4 | AI16: 1 | AJ16: 1 | AK16: 3 | AL16: 3 | AM16: 1 | AN16: 1 | AO16: 1 | AP16: 1 | AR16: 10 | AS16: 0 | AT16: 5 | AU16: 15 | AV16: 0 | AW16: 0 | AX16: 0 | AY16: 0 | AZ16: 0 | BA16: 15
A17: 16 | B17: 19445770-7 | C17: 19445770 | D17: ROJAS | E17: POBLETE | F17: KATIUSCA AYLEN | G17: GENERALISTA DE RRHH | I17: I | J17: F | K17: 5X2 | L17: 1770000002 | M17: 1 | N17: 1 | O17: 3 | P17: 3 | Q17: 3 | R17: 1 | S17: 1 | T17: 1 | U17: 1 | V17: 1 | W17: 3 | X17: 3 | Y17: 1 | Z17: 1 | AA17: 1 | AB17: 1 | AC17: 1 | AD17: 3 | AE17: 3 | AF17: 1 | AG17: 1 | AH17: 1 | AI17: 1 | AJ17: 1 | AK17: 3 | AL17: 3 | AM17: 1 | AN17: 1 | AO17: 1 | AP17: 1 | AR17: 21 | AS17: 0 | AT17: 9 | AU17: 0 | AV17: 0 | AW17: 0 | AX17: 0 | AY17: 0 | AZ17: 0 | BA17: 30
A18: 17 | B18: 24718250-0 | C18: 24718250 | D18: MOSQUERA | E18: VALDERRAMA | F18: GUILLERMO | G18: RECEPCIONISTA ADMINISTRATIVO | I18: I | J18: M | K18: 5X2 | L18: 1770000002 | M18: 1 | N18: 1 | O18: 3 | P18: 3 | Q18: 3 | R18: 1 | S18: 1 | T18: 1 | U18: 1 | V18: 1 | W18: 3 | X18: 3 | Y18: 1 | Z18: 1 | AA18: 1 | AB18: 1 | AC18: 1 | AD18: 3 | AE18: 3 | AF18: 1 | AG18: 1 | AH18: 1 | AI18: 1 | AJ18: 1 | AK18: 3 | AL18: 3 | AM18: 1 | AN18: 1 | AO18: 1 | AP18: 1 | AR18: 21 | AS18: 0 | AT18: 9 | AU18: 0 | AV18: 0 | AW18: 0 | AX18: 0 | AY18: 0 | AZ18: 0 | BA18: 30
A19: 18 | B19: 9717041-K | C19: 9717041 | D19: OLIVARES | E19: DIAZ | F19: GONZALO LUIS | G19: ENCARGADO DE COMPRAS Y ABASTECIMIENTO | I19: I | J19: M | K19: 5X2 | L19: 1790000088 | M19: 1 | N19: 1 | O19: 3 | P19: 3 | Q19: 3 | R19: 1 | S19: 1 | T19: 1 | U19: 1 | V19: 1 | W19: 3 | X19: 3 | Y19: 1 | Z19: 1 | AA19: 1 | AB19: 1 | AC19: 1 | AD19: 3 | AE19: 3 | AF19: 1 | AG19: 1 | AH19: 1 | AI19: 1 | AJ19: 1 | AK19: 3 | AL19: 3 | AM19: 1 | AN19: 1 | AO19: 1 | AP19: 1 | AR19: 21 | AS19: 0 | AT19: 9 | AU19: 0 | AV19: 0 | AW19: 0 | AX19: 0 | AY19: 0 | AZ19: 0 | BA19: 30 | BW19: 110000
A20: 19 | B20: 20091945-9 | C20: 20091945 | D20: JIMENEZ | E20: BUGUEÑO | F20: DENIS MARCELA | G20: ADMINISTRATIVO | I20: I | J20: F | K20: 5X2 | L20: 1790000091 | M20: 4 | N20: 4 | O20: 4 | P20: 4 | Q20: 4 | R20: 4 | S20: 4 | T20: 4 | U20: 4 | V20: 4 | W20: 4 | X20: 4 | Y20: 4 | Z20: 4 | AA20: 4 | AB20: 4 | AC20: 4 | AD20: 4 | AE20: 4 | AF20: 4 | AG20: 4 | AH20: 4 | AI20: 4 | AJ20: 4 | AK20: 4 | AL20: 4 | AM20: 4 | AN20: 4 | AO20: 4 | AP20: 4 | AR20: 0 | AS20: 0 | AT20: 0 | AU20: 30 | AV20: 0 | AW20: 0 | AX20: 0 | AY20: 0 | AZ20: 0 | BA20: 0
A21: 20 | B21: 11922653-8 | C21: 11922653 | D21: ANDRADE | E21: CASTRO | F21: LUIS BERNARDO | G21: ENCARGADO DE MANTENCION | I21: I | J21: M | K21: 5X2 | L21: 1790000088 | M21: 4 | N21: 4 | O21: 4 | P21: 4 | Q21: 4 | R21: 4 | S21: 1 | T21: 1 | U21: 1 | V21: 1 | W21: 3 | X21: 3 | Y21: 1 | Z21: 1 | AA21: 1 | AB21: 1 | AC21: 1 | AD21: 3 | AE21: 3 | AF21: 1 | AG21: 1 | AH21: 1 | AI21: 1 | AJ21: 1 | AK21: 3 | AL21: 3 | AM21: 1 | AN21: 1 | AO21: 1 | AP21: 1 | AR21: 18 | AS21: 0 | AT21: 6 | AU21: 6 | AV21: 0 | AW21: 0 | AX21: 0 | AY21: 0 | AZ21: 0 | BA21: 24
A22: 21 | B22: 13205525-4 | C22: 13205525 | D22: ORTIZ | E22: MEDEL | F22: SEBASTIAN DEL CARMEN | G22: CONDUCTOR CAMION RAMPA | H22: 44136 | I22: D | J22: M | K22: 5X2 | L22: 1790000088 | M22: 5 | N22: 5 | O22: 5 | P22: 5 | Q22: 5 | R22: 9 | S22: 9 | T22: 9 | U22: 9 | V22: 9 | W22: 9 | X22: 9 | Y22: 9 | Z22: 9 | AA22: 9 | AB22: 9 | AC22: 9 | AD22: 9 | AE22: 9 | AF22: 9 | AG22: 9 | AH22: 9 | AI22: 9 | AJ22: 9 | AK22: 9 | AL22: 9 | AM22: 9 | AN22: 9 | AO22: 9 | AP22: 9 | AR22: 0 | AS22: 0 | AT22: 0 | AU22: 0 | AV22: 5 | AW22: 0 | AX22: 0 | AY22: 0 | AZ22: 25 | BA22: 30
A23: 22 | B23: 9912965-4 | C23: 9912965 | D23: PEREZ | E23: OSSANDON | F23: ORIEL EDUARDO | G23: SUPERVISOR CONTROL CALIDAD | I23: I | J23: M | K23: 5X2 | L23: 1740000002 | M23: 9 | N23: 9 | O23: 9 | P23: 9 | Q23: 9 | R23: 9 | S23: 1 | T23: 1 | U23: 1 | V23: 1 | W23: 3 | X23: 3 | Y23: 9 | Z23: 9 | AA23: 9 | AB23: 9 | AC23: 9 | AD23: 9 | AE23: 9 | AF23: 9 | AG23: 9 | AH23: 9 | AI23: 9 | AJ23: 9 | AK23: 9 | AL23: 9 | AM23: 9 | AN23: 9 | AO23: 9 | AP23: 9 | AR23: 4 | AS23: 0 | AT23: 2 | AU23: 0 | AV23: 0 | AW23: 0 | AX23: 0 | AY23: 0 | AZ23: 24 | BA23: 30 | BE23: 519000 | BF23: Bono complemento sueldo | CH23: CENTRO DE COSTO (SIN FAENA)
A24: 23 | B24: 11876153-7 | C24: 11876153 | D24: HERNANDEZ | E24: DE LA FUENTE | F24: FERNANDO HIPOLITO | G24: SUPERVISRO VISITADOR E INSTRUCTOR | I24: I | J24: M | K24: 5X2 | L24: 1790000090 | M24: 1 | N24: 1 | O24: 3 | P24: 3 | Q24: 3 | R24: 1 | S24: 3 | T24: 3 | U24: 1 | V24: 1 | W24: 1 | X24: 1 | Y24: 1 | Z24: 3 | AA24: 3 | AB24: 1 | AC24: 1 | AD24: 1 | AE24: 1 | AF24: 1 | AG24: 3 | AH24: 3 | AI24: 1 | AJ24: 1 | AK24: 1 | AL24: 1 | AM24: 1 | AN24: 1 | AO24: 1 | AP24: 1 | AR24: 21 | AS24: 0 | AT24: 9 | AU24: 0 | AV24: 0 | AW24: 0 | AX24: 0 | AY24: 0 | AZ24: 0 | BA24: 30 | BW24: 110000 | CE24: 77281
A25: 24 | B25: 20051179-4 | C25: 20051179 | D25: HIDALGO | E25: SEGOVIA | F25: PATRICIO ANDRÉS | G25: TECNICO EN SISTEMA GEOMEMB | H25: 46113 | I25: D | J25: M | K25: 5X2 | L25: 1790000088 | M25: 1 | N25: 1 | O25: 3 | P25: 3 | Q25: 3 | R25: 1 | S25: 3 | T25: 3 | U25: 1 | V25: 1 | W25: 1 | X25: 1 | Y25: 1 | Z25: 3 | AA25: 3 | AB25: 1 | AC25: 1 | AD25: 1 | AE25: 1 | AF25: 1 | AG25: 3 | AH25: 3 | AI25: 1 | AJ25: 1 | AK25: 1 | AL25: 1 | AM25: 1 | AN25: 1 | AO25: 1 | AP25: 1 | AR25: 21 | AS25: 0 | AT25: 9 | AU25: 0 | AV25: 0 | AW25: 0 | AX25: 0 | AY25: 0 | AZ25: 0 | BA25: 30
A26: 25 | B26: 20308051-4 | C26: 20308051 | D26: RODRIGUEZ | E26: CORTES | F26: KEVIN ALEJANDRO | G26: TECNICO EN SISTEMA GEOMEMB | H26: 46113 | I26: D | J26: M | K26: 5X2 | L26: 1790000088 | M26: 1 | N26: 1 | O26: 3 | P26: 3 | Q26: 3 | R26: 1 | S26: 3 | T26: 3 | U26: 1 | V26: 1 | W26: 1 | X26: 1 | Y26: 1 | Z26: 3 | AA26: 3 | AB26: 1 | AC26: 1 | AD26: 1 | AE26: 1 | AF26: 1 | AG26: 3 | AH26: 3 | AI26: 1 | AJ26: 1 | AK26: 1 | AL26: 1 | AM26: 1 | AN26: 1 | AO26: 1 | AP26: 1 | AR26: 21 | AS26: 0 | AT26: 9 | AU26: 0 | AV26: 0 | AW26: 0 | AX26: 0 | AY26: 0 | AZ26: 0 | BA26: 30
A27: 26 | B27: 17659588-4 | C27: 17659588 | D27: FOURNIEL | E27: NAVARRO | F27: ALVARO RODRIGO | G27: ADMINISTRADOR DE CONTRATO | I27: I | J27: M | K27: 5X2 | L27: 1740000002 | AR27: 0 | AS27: 0 | AT27: 0 | AU27: 0 | AV27: 0 | AW27: 0 | AX27: 0 | AY27: 0 | AZ27: 0 | BA27: 0 | BB27: 2000000 | CH27: SOLO PAGAR BONO (LIQUIDO 1.6) - CENTRO COSTO SIN FAENA
A28: 27 | B28: 14016056-3 | C28: 14016056 | D28: VALDIVIA | E28: TORRES | F28: GONZALO EDUARDO | G28: GENERALISTA GESTION PERSONAS | H28: 46104 | I28: I | J28: M | K28: 5X2 | L28: 1720000001 | M28: 1 | N28: 1 | O28: 3 | P28: 3 | Q28: 3 | R28: 1 | S28: 3 | T28: 3 | U28: 1 | V28: 1 | W28: 1 | X28: 1 | Y28: 1 | Z28: 3 | AA28: 3 | AB28: 1 | AC28: 1 | AD28: 1 | AE28: 1 | AF28: 1 | AG28: 3 | AH28: 3 | AI28: 1 | AJ28: 1 | AK28: 1 | AL28: 1 | AM28: 1 | AN28: 1 | AO28: 1 | AP28: 1 | AR28: 21 | AS28: 0 | AT28: 9 | AU28: 0 | AV28: 0 | AW28: 0 | AX28: 0 | AY28: 0 | AZ28: 0 | BA28: 30
A29: 28 | B29: 13012039-3 | C29: 13012039 | D29: LOBOS | E29: PIZARRO | F29: JORGE HUMBERTO | G29: JEFE CONTROL DE CALIDAD | H29: 46118 | I29: I | J29: M | K29: 5X2 | L29: 1790000088 | R29: 1 | S29: 1 | T29: 1 | U29: 1 | V29: 1 | W29: 3 | X29: 3 | Y29: 1 | Z29: 1 | AA29: 1 | AB29: 1 | AC29: 1 | AD29: 3 | AE29: 3 | AF29: 1 | AG29: 1 | AH29: 1 | AI29: 1 | AJ29: 1 | AK29: 3 | AL29: 3 | AM29: 1 | AN29: 1 | AO29: 1 | AP29: 1 | AR29: 19 | AS29: 0 | AT29: 6 | AU29: 0 | AV29: 0 | AW29: 0 | AX29: 0 | AY29: 0 | AZ29: 0 | BA29: 25

Sheet 04_2026_Techint-RT
A1: Nº | B1: RUT (sin puntos y con guion) | C1: ID (rut sin puntos, sin guión ni digito vertificador) | D1: APELLIDO PATERNO | E1: APELLIDO MATERNO | F1: NOMBRES | G1: CARGO | H1: INICIO DE CONTRATO | I1: D/I | J1: GENERO M/F | K1: TURNO (5x2-4x3-14x14 -art22) | L1: CC | M1: 1 | N1: 2 | O1: 3 | P1: 4 | Q1: 5 | R1: 6 | S1: 7 | T1: 8 | U1: 9 | V1: 10 | W1: 11 | X1: 12 | Y1: 13 | Z1: 14 | AA1: 15 | AB1: 16 | AC1: 17 | AD1: 18 | AE1: 19 | AF1: 20 | AG1: 21 | AH1: 22 | AI1: 23 | AJ1: 24 | AK1: 25 | AL1: 26 | AM1: 27 | AN1: 28 | AO1: 29 | AP1: 30 | AQ1: 31 | AR1: (1) | AS1: (2) | AT1: (3) | AU1: (4) | AV1: (5) | AW1: (6) | AX1: (7) | AY1: (8) | AZ1: (9) | BA1: T.D.T. | BB1: 1033-Bono Gestión Variable | BC1: 1029-Bono Compensatorio descanso | BD1: Justificación Bono 10-29 (Compensatorio descanso) | BE1: 1034-Bono Incentivo variable | BF1: Justificación Bono 1034 (Incentivo variable) | BG1: 1140-Bono Responsabilidad 2 | BH1: Justificación 1140 (Bono Responsabilidad) | BI1: 1041-Bono Terreno (Exclusivo proyecto Techint-CMDIC) | BJ1: 1031-Bono Escolaridad I/T (Uso exclusivo Area de Compensaciones) | BK1: 1092-Diferencia de haber | BL1: Justificación Bono 1092 (Diferencia de Haber) | BM1: Cantidad de feriados del mes | BN1: 1082-Bono Compens. Feriado | BO1: 1020-Aguinaldo I/T | BP1: 1140-Bono de Permanencia (Plan de Beneficios) | BQ1: Bono Seguridad BESALCO-MEL | BR1: Bono Q1 (Exclusivo Collahuasi) | BS1: Bono Q2 (Exclusivo Collahuasi) | BT1: Bono Q3 (Exclusivo Collahuasi) | BU1: Bono Q4 (Exclusivo Collahuasi) | BV1: Bono RSA (Exclusivo Collahuasi) | BW1: 1044-Asignación Colación | BX1: Justificación Asignacion Colacion | BY1: 1165-Asignación Movilización 2 | BZ1: Justificación Asignación Movilización 2 | CA1: 1172-Viatico 2 | CB1: Justificación Viatico | CC1: 1073-Otras Asignaciones N/I (Beneficios) | CD1: Justificaciión de Asignación (Detalle del beneficio) | CE1: 1032-Bono Escolaridad N/I | CF1: 1124-Asignación familiar Retroactiva | CG1: Descuento por aporte voluntario | CH1: Observaciones generales | CI1: ACUERDO MARCO ACCIONA-CODELCO | CJ1: GRATIFICACION ACUERD MARCO ACCIONA-CODELCO2 | CK1: DIAS ADICIONALES CHIQUICAMATA | CL1: BONO PARTICIPACION CHIQUI
A2: 1 | B2: 9187205-6 | C2: 9187205 | D2: HERRERA | E2: VERA | F2: OSCAR CRISTIAN | G2: GERENTE DE PROYECTOS | H2: 45676 | I2: I | J2: M | K2: 4X3 | L2: 1790000088 | M2: 1 | N2: 1 | O2: 3 | P2: 3 | Q2: 3 | R2: 1 | S2: 1 | T2: 1 | U2: 1 | V2: 3 | W2: 3 | X2: 3 | Y2: 1 | Z2: 1 | AA2: 1 | AB2: 1 | AC2: 3 | AD2: 3 | AE2: 3 | AF2: 1 | AG2: 1 | AH2: 1 | AI2: 1 | AJ2: 3 | AK2: 3 | AL2: 3 | AM2: 1 | AN2: 1 | AO2: 1 | AP2: 1 | AR2: 18 | AS2: 0 | AT2: 12 | AU2: 0 | AV2: 0 | AW2: 0 | AX2: 0 | AY2: 0 | AZ2: 0 | BA2: 30 | BE2: 328000 | BF2: Bono para llegar a sueldo pactado | BM2: 0
A3: 2 | B3: 9460969-0 | C3: 9460969 | D3: ARANDA | E3: CAQUEO | F3: LUIS ALFONSO | G3: EXPEDITOR | H3: 45712 | I3: I | J3: M | K3: A | L3: 1790000088 | M3: 1 | N3: 3 | O3: 3 | P3: 3 | AR3: 1 | AS3: 0 | AT3: 3 | AU3: 0 | AV3: 0 | AW3: 0 | AX3: 0 | AY3: 0 | AZ3: 0 | BA3: 4 | BC3: 193599 | BD3: Corresponde a dia pend. Cambio jornada 4x3 transición. | BE3: 33333.333 | BF3: para ajustar sueldo pactado a 1.700.000.- | BM3: 0 | BP3: 75000
A4: 3 | B4: 10420797-9 | C4: 10420797 | D4: IRRIBARRA | E4: PEÑA | F4: HECTOR LEONIDAS | G4: JEFE RECURSOS HUMANOS PROYECTO | H4: 45704 | I4: I | J4: M | K4: 4X3 | L4: 1790000088 | M4: 1 | N4: 1 | O4: 3 | P4: 3 | Q4: 3 | R4: 1 | S4: 1 | T4: 1 | U4: 1 | V4: 3 | W4: 3 | X4: 3 | Y4: 1 | Z4: 1 | AA4: 1 | AB4: 1 | AC4: 3 | AD4: 3 | AE4: 3 | AF4: 1 | AG4: 1 | AH4: 1 | AI4: 1 | AJ4: 3 | AK4: 3 | AL4: 3 | AM4: 1 | AN4: 1 | AO4: 1 | AP4: 1 | AR4: 18 | AS4: 0 | AT4: 12 | AU4: 0 | AV4: 0 | AW4: 0 | AX4: 0 | AY4: 0 | AZ4: 0 | BA4: 30 | BC4: 230799 | BD4: 3 DIAS DESCANSO MAYO-26 | BM4: 0 | CA4: 72000 | CB4: PAGO TRASLADO ALIMENTACION DIC-ENERO-ESPAÑA A TOKY EN EFECTIVO
A5: 4 | B5: 10603186-K | C5: 10603186 | D5: LEON | E5: OLEA | F5: JAIME ANTONIO | G5: TECNICO RECURSOS HUMANOS PROYECTO | H5: 45748 | I5: I | J5: M | K5: A | L5: 1790000088 | M5: 1 | N5: 1 | O5: 3 | P5: 3 | Q5: 3 | R5: 1 | S5: 1 | T5: 1 | U5: 1 | V5: 3 | W5: 3 | X5: 3 | Y5: 1 | Z5: 1 | AA5: 1 | AB5: 1 | AC5: 3 | AD5: 3 | AE5: 3 | AF5: 1 | AG5: 1 | AH5: 1 | AI5: 1 | AJ5: 3 | AK5: 3 | AL5: 3 | AM5: 1 | AN5: 1 | AO5: 1 | AP5: 1 | AR5: 18 | AS5: 0 | AT5: 12 | AU5: 0 | AV5: 0 | AW5: 0 | AX5: 0 | AY5: 0 | AZ5: 0 | BA5: 30 | BC5: 614997 | BD5: 9 DIAS DESCANSO MAYO-26 | BE5: 500000 | BF5: Realizar actividades de ADMIN. CAMPAMENTO | BM5: 0
A6: 5 | B6: 10957493-7 | C6: 10957493 | D6: GONZALEZ | E6: QUINZACARA | F6: LUIS ARNOLDO | G6: CAPATAZ GEOSINTETICOS | H6: 45809 | I6: D | J6: M | K6: B | L6: 1790000088 | M6: 3 | N6: 3 | O6: 3 | P6: 3 | Q6: 3 | R6: 3 | S6: 1 | T6: 1 | U6: 2 | V6: 2 | W6: 2 | X6: 2 | Y6: 2 | Z6: 2 | AA6: 2 | AB6: 2 | AC6: 2 | AD6: 2 | AE6: 2 | AF6: 2 | AG6: 2 | AH6: 3 | AI6: 3 | AJ6: 3 | AK6: 3 | AL6: 3 | AM6: 3 | AN6: 3 | AO6: 3 | AP6: 3 | AR6: 2 | AS6: 13 | AT6: 15 | AU6: 0 | AV6: 0 | AW6: 0 | AX6: 0 | AY6: 0 | AZ6: 0 | BA6: 30 | BC6: 258335 | BD6: 5 DIAS DESCANSO MAYO-26 | BM6: 0 | BP6: 150000
A7: 6 | B7: 11265430-5 | C7: 11265430 | D7: FAUNDEZ | E7: ORTIZ | F7: CESAR HERNAN | G7: TOPÓGRAFO - NIVELADOR | H7: 45748 | I7: I | J7: M | K7: 4x3 | L7: 1790000088 | M7: 1 | N7: 1 | O7: 3 | P7: 3 | Q7: 3 | R7: 1 | S7: 1 | T7: 1 | U7: 1 | V7: 3 | W7: 3 | X7: 3 | Y7: 1 | Z7: 1 | AA7: 1 | AB7: 1 | AC7: 3 | AD7: 3 | AE7: 3 | AF7: 1 | AG7: 1 | AH7: 1 | AI7: 1 | AJ7: 3 | AK7: 3 | AL7: 3 | AM7: 1 | AN7: 1 | AO7: 1 | AP7: 1 | AR7: 18 | AS7: 0 | AT7: 12 | AU7: 0 | AV7: 0 | AW7: 0 | AX7: 0 | AY7: 0 | AZ7: 0 | BA7: 30 | BE7: 837000 | BF7: Bono asignacion de obra | BM7: 0
A8: 7 | B8: 11734191-7 | C8: 11734191 | D8: TORRES | E8: LOPEZ | F8: LUIS EDUARDO | G8: OPERADOR CAMIÓN PLUMA | H8: 45756 | I8: D | J8: M | K8: A | L8: 1790000088 | M8: 1 | N8: 1 | O8: 1 | P8: 1 | Q8: 1 | R8: 1 | S8: 1 | T8: 1 | U8: 1 | V8: 1 | W8: 1 | X8: 1 | Y8: 1 | Z8: 1 | AA8: 1 | AB8: 1 | AC8: 1 | AD8: 1 | AE8: 1 | AF8: 1 | AG8: 1 | AH8: 2 | AI8: 2 | AJ8: 2 | AK8: 2 | AL8: 2 | AM8: 2 | AN8: 2 | AO8: 2 | AP8: 2 | AR8: 21 | AS8: 9 | AT8: 0 | AU8: 0 | AV8: 0 | AW8: 0 | AX8: 0 | AY8: 0 | AZ8: 0 | BA8: 30 | BM8: 0
A9: 8 | B9: 12038137-7 | C9: 12038137 | D9: CORTES | E9: LÓPEZ | F9: MARCELO ANTONIO | G9: MAESTRO SEGUNDA GEOSINTETICOS | H9: 45924 | I9: D | J9: M | K9: B | L9: 1790000088 | M9: 1 | N9: 1 | O9: 1 | P9: 1 | Q9: 1 | R9: 1 | S9: 1 | T9: 1 | U9: 1 | V9: 1 | W9: 1 | AR9: 11 | AS9: 0 | AT9: 0 | AU9: 0 | AV9: 0 | AW9: 0 | AX9: 0 | AY9: 0 | AZ9: 0 | BA9: 11 | BM9: 0
A10: 9 | B10: 12612919-k | C10: 12612919 | D10: HERRERA | E10: CORTES | F10: JUVENAL HUMBERTO | G10: AYUDANTE GEOSINTETICOS | H10: 45858 | I10: D | J10: M | K10: A | L10: 1790000088 | M10: 2 | N10: 2 | O10: 8 | P10: 8 | Q10: 2 | R10: 2 | S10: 2 | T10: 3 | U10: 3 | V10: 3 | W10: 3 | X10: 3 | Y10: 3 | Z10: 3 | AA10: 3 | AB10: 3 | AC10: 3 | AD10: 3 | AE10: 3 | AF10: 3 | AG10: 3 | AH10: 2 | AI10: 2 | AJ10: 2 | AK10: 2 | AL10: 2 | AM10: 2 | AN10: 2 | AO10: 2 | AP10: 2 | AR10: 0 | AS10: 14 | AT10: 14 | AU10: 0 | AV10: 0 | AW10: 0 | AX10: 0 | AY10: 2 | AZ10: 0 | BA10: 30 | BC10: 223803 | BD10: 9 DIAS DESCANSO MAYO-26 | BM10: 2 | BN10: 149200 | BP10: 150000
A11: 10 | B11: 13076470-3 | C11: 13076470 | D11: REHBEIN | E11: GANTES | F11: ANTONIO ALEJANDRO | G11: JEFE DE TERRENO | H11: 45805 | I11: I | J11: M | K11: B | L11: 1790000088 | M11: 3 | N11: 3 | O11: 3 | P11: 3 | Q11: 3 | R11: 3 | S11: 3 | T11: 2 | U11: 2 | V11: 2 | W11: 2 | X11: 2 | Y11: 1 | Z11: 1 | AA11: 2 | AB11: 2 | AC11: 2 | AD11: 2 | AE11: 2 | AF11: 2 | AG11: 2 | AH11: 3 | AI11: 3 | AJ11: 3 | AK11: 3 | AL11: 3 | AM11: 3 | AN11: 3 | AO11: 3 | AP11: 3 | AR11: 2 | AS11: 12 | AT11: 16 | AU11: 0 | AV11: 0 | AW11: 0 | AX11: 0 | AY11: 0 | AZ11: 0 | BA11: 30 | BC11: 598335 | BD11: 5 DIAS DESCANSO MAYO-26 | BE11: 375000 | BF11: Bono ajuste salarial | BM11: 0
A12: 11 | B12: 13172993-6 | C12: 13172993 | D12: GODOY | E12: CORTES | F12: SANDRA ROSARIO | G12: ADMINISTRATIVO OFICINA TECNICA | H12: 45839 | I12: I | J12: F | K12: 4X3 | L12: 1790000088 | M12: 1 | N12: 3 | O12: 3 | P12: 3 | AR12: 1 | AS12: 0 | AT12: 3 | AU12: 0 | AV12: 0 | AW12: 0 | AX12: 0 | AY12: 0 | AZ12: 0 | BA12: 4 | BM12: 0
A13: 12 | B13: 13174740-3 | C13: 13174740 | D13: ROJAS | E13: GERALDO | F13: EUGENIO DAVID | G13: MAESTRO SEGUNDA GEOSINTETICOS | H13: 45846 | I13: D | J13: M | K13: B | L13: 1790000088 | M13: 3 | N13: 3 | O13: 3 | P13: 3 | Q13: 3 | R13: 3 | S13: 3 | T13: 2 | U13: 2 | V13: 2 | W13: 2 | X13: 2 | Y13: 2 | Z13: 2 | AA13: 2 | AB13: 2 | AC13: 2 | AD13: 2 | AE13: 2 | AF13: 2 | AG13: 2 | AH13: 3 | AI13: 3 | AJ13: 3 | AK13: 3 | AL13: 3 | AM13: 3 | AN13: 3 | AO13: 3 | AP13: 3 | AR13: 0 | AS13: 14 | AT13: 16 | AU13: 0 | AV13: 0 | AW13: 0 | AX13: 0 | AY13: 0 | AZ13: 0 | BA13: 30 | BC13: 141665 | BD13: 5 DIAS DESCANSO MAYO-26 | BM13: 0 | BP13: 150000
A14: 13 | B14: 13531208-8 | C14: 13531208 | D14: ARAYA | E14: REYES | F14: MARCO ANTONIO | G14: JEFE PREVENCIÓN DE RIESGOS | H14: 45689 | I14: I | J14: M | K14: 4X3 | L14: 1790000088 | M14: 1 | N14: 1 | O14: 3 | P14: 3 | Q14: 3 | R14: 1 | S14: 1 | T14: 1 | U14: 1 | V14: 3 | W14: 3 | X14: 3 | Y14: 1 | Z14: 1 | AA14: 1 | AB14: 1 | AC14: 3 | AD14: 3 | AE14: 3 | AF14: 1 | AG14: 1 | AH14: 1 | AI14: 1 | AJ14: 3 | AK14: 3 | AL14: 3 | AM14: 1 | AN14: 1 | AO14: 1 | AP14: 1 | AR14: 18 | AS14: 0 | AT14: 12 | AU14: 0 | AV14: 0 | AW14: 0 | AX14: 0 | AY14: 0 | AZ14: 0 | BA14: 30 | BE14: 1634000 | BF14: Bono para llegar a monto asignado | BM14: 0 | CE14: 77281
A15: 14 | B15: 13702938-3 | C15: 13702938 | D15: VEGA | E15: GUERRERO | F15: VICTOR ANDRES | G15: SUPERVISOR GEOSINTETICOS | H15: 45702 | I15: I | J15: M | K15: A | L15: 1790000088 | M15: 2 | N15: 2 | O15: 8 | P15: 8 | Q15: 2 | R15: 2 | S15: 2 | T15: 3 | U15: 3 | V15: 3 | W15: 3 | X15: 3 | Y15: 3 | Z15: 3 | AA15: 3 | AB15: 3 | AC15: 3 | AD15: 3 | AE15: 3 | AF15: 3 | AG15: 3 | AH15: 2 | AI15: 2 | AJ15: 2 | AK15: 2 | AL15: 2 | AM15: 2 | AN15: 2 | AO15: 2 | AP15: 2 | AR15: 0 | AS15: 14 | AT15: 14 | AU15: 0 | AV15: 0 | AW15: 0 | AX15: 0 | AY15: 2 | AZ15: 0 | BA15: 30 | BC15: 732303 | BD15: 9 DIAS DESCANSO MAYO-26 | BM15: 2 | BN15: 488018 | BP15: 150000
A16: 15 | B16: 15018611-0 | C16: 15018611 | D16: GUERRA | E16: YAPOR | F16: JORGE ANDRES | G16: SUBGERENTE CONTRATOS Y SERVICIOS | H16: 45689 | I16: I | J16: M | K16: 4X3 | L16: 1790000088 | M16: 1 | N16: 1 | O16: 3 | P16: 3 | Q16: 3 | R16: 1 | S16: 1 | T16: 1 | U16: 1 | V16: 3 | W16: 3 | X16: 3 | Y16: 1 | Z16: 1 | AA16: 1 | AB16: 1 | AC16: 3 | AD16: 3 | AE16: 3 | AF16: 1 | AG16: 1 | AH16: 1 | AI16: 1 | AJ16: 3 | AK16: 3 | AL16: 3 | AM16: 1 | AN16: 1 | AO16: 1 | AP16: 1 | AR16: 18 | AS16: 0 | AT16: 12 | AU16: 0 | AV16: 0 | AW16: 0 | AX16: 0 | AY16: 0 | AZ16: 0 | BA16: 30 | BB16: 1508437 | BM16: 0 | CA16: 180000 | CB16: Gastos aseo depa
